<?xml version="1.0" ?>
<!-- =================================================================================== -->
<!-- |    This document was autogenerated by xacro from walking_excavator.urdf1.xacro  | -->
<!-- |    EDITING THIS FILE BY HAND IS NOT RECOMMENDED                                 | -->
<!-- =================================================================================== -->
<robot name="walking_excavator" xmlns:xacro="http://www.ros.org/wiki/xacro">
  <material name="Yellow">
    <color rgba="1.0 1.0 0.0 1.0"/>
  </material>
  <material name="Gray">
    <color rgba="0.2 0.2 0.2 1.0"/>
  </material>
  <material name="Black">
    <color rgba="0.1 0.1 .1 1.0"/>
  </material>
  <material name="Orange">
    <color rgba="1.0 0.423529411765 0.0392156862745 1.0"/>
  </material>
  <material name="Gray2">
    <color rgba="0.00392156862745 0.423529411765 0.392156862745 1.0"/>
  </material>
  <material name="Blue">
    <color rgba="0 0.08 0.3 1.0"/>
  </material>
  <material name="White">
    <color rgba="1 1 1 1.0"/>
  </material>
  <gazebo reference="cab">
    <material>Gazebo/Orange</material>
  </gazebo>
  <gazebo reference="bucket">
    <material>Gazebo/Blue</material>
  </gazebo>
  <gazebo reference="boom_link1">
    <material>Gazebo/Yellow</material>
  </gazebo>
  <gazebo reference="boom_link2">
    <material>Gazebo/Yellow</material>
  </gazebo>
  <gazebo reference="body">
    <material>Gazebo/Gray2</material>
  </gazebo>
  <link name="base_link">
    <gazebo reference="base_link">
      <material>Gazebo/Orange</material>
      <gravity>true</gravity>
    </gazebo>
  </link>
  <joint name="j_walking_excavator_attachment" type="fixed">
    <parent link="base_link"/>
    <child link="body"/>
    <origin rpy="0 0 0" xyz="0 0 0"/>
  </joint>
  <link name="body">
    <inertial>
      <origin rpy="0 0 0" xyz="0 0 0"/>
      <mass value="1635"/>
      <!-- 8635 -->
      <inertia ixx="1031.25" ixy="0.000382827" ixz="0.0010607499" iyy="2218.333333" iyz="0.1148162032" izz="3249.583333"/>
    </inertial>
    <visual>
      <material name="Yellow"/>
      <origin rpy="0 0 0" xyz="0 0 0"/>
      <geometry>
        <mesh filename="package://walking_excavator_urdf/xacro_manzi/base_link_exc1.stl" scale="0.5 0.5 0.8"/>
      </geometry>
    </visual>
    <collision>
      <material name="Red"/>
      <origin rpy="0 0 0" xyz="0 0 0"/>
      <geometry>
        <mesh filename="package://walking_excavator_urdf/xacro_manzi/base_link_exc1.stl" scale="0.1 0.1 0.1"/>
      </geometry>
    </collision>
  </link>
  <joint name="revolving_cab_angle" type="revolute">
    <parent link="body"/>
    <child link="cab"/>
    <origin rpy="0 0 0" xyz="0 0 1.5"/>
    <axis xyz="0 0 1"/>
    <limit effort="12000" lower="-3.05432" upper="+3.05432" velocity="0.1415926535897931"/>
    <dynamics damping="300.7" friction="40.0"/>
  </joint>
  <link name="cab">
    <inertial>
      <origin rpy="0 0 0" xyz="0 0 2.1"/>
      <mass value="880.1"/>
      <!-- 14.1 -->
      <inertia ixx="150" ixy="0.000382827" ixz="0.0010607499" iyy="322.666667" iyz="0.1148162032" izz="472.666667"/>
    </inertial>
    <visual>
      <!-- <material name="Yellow"/> -->
      <material name="Orange"/>
      <origin rpy="0 0 0" xyz="0 -0.5 -0.0"/>
      <geometry>
        <!-- <box size="1.3 1.85 5.0"/> scale="0.001 0.001 0.001" -->
        <mesh filename="package://walking_excavator_urdf/xacro_manzi/cab2.stl" scale="1 1 1"/>
        <!-- <mesh filename="package://walking_excavator_urdf/urdf/meshes/base_boom1.stl" scale="0.5 0.5 0.8"/>  package://walking_excavator_urdf/urdf/meshes/cab2.stl-->
      </geometry>
    </visual>
    <collision>
      <material name="Black"/>
      <origin rpy="0 0 0" xyz="0.0 0.0 5.0"/>
      <geometry>
        <box size="1.3 1.85 5.0"/>
      </geometry>
    </collision>
  </link>
  <joint name="cab_base" type="fixed">
    <parent link="cab"/>
    <child link="cab_boom"/>
    <origin rpy="0 0 0" xyz="0 0 1.0"/>
    <axis xyz="0 0 1"/>
    <limit effort="10" lower="-3.05432" upper="+3.05432" velocity="3.1415926535897931"/>
  </joint>
  <link name="cab_boom">
    <inertial>
      <origin rpy="0 0 0" xyz="0 0.5 -2.2"/>
      <mass value="1.1"/>
      <!-- 14.1 -->
      <inertia ixx="5.01" ixy="0.000382827" ixz="0.0010607499" iyy="5.666667" iyz="0.1148162032" izz="5.666667"/>
    </inertial>
    <visual>
      <material name="Orange"/>
      <origin rpy="0 0 0" xyz="0 0.5 -2.0"/>
      <geometry>
        <mesh filename="package://walking_excavator_urdf/xacro_manzi/body_boom_base.stl" scale="0.8 0.8 0.8"/>
        <!-- <mesh filename="package://walking_excavator_urdf/urdf/meshes/base_boom1.stl" scale="0.5 0.5 0.8"/> -> -->
      </geometry>
    </visual>
    <collision>
      <material name="Gray"/>
      <origin rpy="0 0 0" xyz="0.0 0.0 0.0"/>
      <geometry>
        <box size="0.3 0.85 0.1"/>
      </geometry>
    </collision>
  </link>
  <!-- Links -->
  <link name="stabilizer_cylinder_front_left">
    <inertial>
      <origin rpy="0 0 0" xyz="0.05 0 0"/>
      <mass value="100.0"/>
      <inertia ixx="6.0061849" ixy="0.0" ixz="0.000" iyy="6.0061849" iyz="0.000" izz="6.0034656"/>
    </inertial>
    <visual>
      <material name="Black"/>
      <origin rpy="0 0 0" xyz="0 0 0"/>
      <geometry>
        <mesh filename="package://sherpa_tt_urdf/meshes/leg/steeringPivot.stl" scale="0.001 0.001 0.002"/>
      </geometry>
    </visual>
    <collision>
      <material name="Red"/>
      <origin rpy="0 0 0" xyz="0 0 -0.05"/>
      <geometry>
        <cylinder length="0.25" radius="0.08"/>
      </geometry>
    </collision>
  </link>
  <link name="swivel_base_front_left">
    <inertial>
      <origin rpy="0 0 0" xyz="0.2 0 0"/>
      <mass value="100.0"/>
      <inertia ixx="5.0034482759" ixy="0.00" ixz="0.000" iyy="5.0172413793" iyz="0.00" izz="5.0172413793"/>
    </inertial>
    <visual>
      <material name="Yellow"/>
      <origin rpy="0 0 0" xyz="0 0 0"/>
      <geometry>
        <mesh filename="package://sherpa_tt_urdf/meshes/leg/innerStrut.stl" scale="0.0009 0.006 0.002"/>
      </geometry>
    </visual>
    <collision>
      <material name="Red"/>
      <origin rpy="0 0 0" xyz="0.2 0 0.0"/>
      <geometry>
        <box size="0.50 0.15 0.15"/>
      </geometry>
    </collision>
  </link>
  <link name="axle_front_left">
    <inertial>
      <origin rpy="0 0 0" xyz="0 0 0"/>
      <mass value="320.0"/>
      <inertia ixx="249.0103626943" ixy="1.0004710316" ixz="0.0014130947" iyy="249.0122468205" iyz="0" izz="19.2028261894"/>
    </inertial>
    <visual>
      <material name="Black"/>
      <origin rpy="0 0 0" xyz="0 0 0"/>
      <geometry>
        <mesh filename="package://sherpa_tt_urdf/meshes/leg/outerStrut.stl" scale="0.0041 0.004 0.004"/>
      </geometry>
    </visual>
    <!--collision>
            <material name="Red"/>
            <origin xyz="0.15 0.0 0.08" rpy="0 0 0"/>
            <geometry>               
                <box size="0.06 0.14 0.4"/>
            </geometry>
        </collision-->
  </link>
  <link name="hub_front_left">
    <inertial>
      <origin rpy="0 0 0" xyz="0.2 0 0"/>
      <mass value="180.0"/>
      <inertia ixx="15.0008748906" ixy="0.0008748906" ixz="0.0" iyy="24.6157480315" iyz="0.0" izz="20.6148731409"/>
    </inertial>
    <visual>
      <material name="Yellow"/>
      <origin rpy="0 -1.6 0" xyz="0 0 -0.3"/>
      <geometry>
        <mesh filename="package://sherpa_tt_urdf/meshes/leg/driveUnit.stl" scale="0.002 0.002 0.002"/>
      </geometry>
    </visual>
    <!--collision>
                <material name="Red"/>
                <origin xyz="0.2 0 0.0" rpy="0 0 0"/>
                <geometry>               
                                     <box size="0.50 0.05 0.1"/>
                </geometry>
            </collision-->
  </link>
  <!-- -->
  <link name="hub_tilt_front_left">
    <inertial>
      <origin rpy="0 0 0" xyz="0.2 0 0"/>
      <mass value="10.0"/>
      <inertia ixx="15.0008748906" ixy="0.0008748906" ixz="0.0" iyy="24.6157480315" iyz="0.0" izz="20.6148731409"/>
    </inertial>
    <visual>
      <material name="Yellow"/>
      <origin rpy="0 0 0" xyz="0 0 0"/>
      <geometry>
        <box size="0.50 0.15 0.15"/>
      </geometry>
    </visual>
    <collision>
      <material name="Red"/>
      <origin rpy="0 0 0" xyz="0.2 0 0.0"/>
      <geometry>
        <box size="0.50 0.05 0.1"/>
      </geometry>
    </collision>
  </link>
  <link name="wheel_front_left">
    <inertial>
      <origin rpy="0 0 0" xyz="0 0 0"/>
      <mass value="280.0"/>
      <inertia ixx="105.012" ixy="0" ixz="0" iyy="105.015" iyz="0" izz="215.021"/>
    </inertial>
    <visual>
      <material name="Black"/>
      <origin rpy="0 0 0" xyz="0 0 0"/>
      <geometry>
        <mesh filename="package://walking_excavator_urdf/xacro_manzi/wheel4.stl" scale="0.35 0.35 0.35"/>
      </geometry>
    </visual>
    <collision>
      <material name="Red"/>
      <origin rpy="0 0 0" xyz="0 0 -0.03 "/>
      <geometry>
        <cylinder length="0.405" radius="0.62"/>
      </geometry>
    </collision>
  </link>
  <!--    <link name="wheel_end_point_link_${limb_name}">
            <inertial>
                <origin xyz="0 0 0" rpy="0 0 0"/>
                <mass value="0.01"/>
                <inertia ixx="0.0001" ixy="0" ixz="0" iyy="0.0001" iyz="0" izz="0.0001"/>
            </inertial>      
            <geometry>      
                <box size="0.01 0.01 0.01"/>     
            </geometry>
        </link>  

        <link name="force_torque_sensor_link_${limb_name}">
            <inertial>
                <origin xyz="0 0 0.0" rpy="0 0 0"/>
                <mass value="0.001"/>
                <inertia ixx="0.001" ixy="0" ixz="0" iyy="0" iyz="0" izz="0"/>
            </inertial>
        </link>            -->
  <!-- Joint -->
  <joint name="stabilizer_angle_front_left" type="revolute">
    <parent link="body"/>
    <child link="stabilizer_cylinder_front_left"/>
    <origin rpy="0 0 0.7854" xyz="0.8 0.8 0"/>
    <axis xyz="0 0 0"/>
    <limit effort="1200000" lower="-.5707963268" upper="0.581661565" velocity="0.3272664626"/>
    <dynamics damping="300.7" friction="400.0"/>
  </joint>
  <joint name="swivel_angle_front_left" type="revolute">
    <parent link="stabilizer_cylinder_front_left"/>
    <child link="swivel_base_front_left"/>
    <origin rpy="-1.570796 0.15 0" xyz="0.1375 0 0"/>
    <axis xyz="0 0 1"/>
    <limit effort="1200000" lower="-0.872664626" upper="0.4967059728" velocity="0.134906585"/>
    <dynamics damping="300.7" friction="400.0"/>
  </joint>
  <joint name="adjustment_leg_length_front_left" type="prismatic">
    <parent link="swivel_base_front_left"/>
    <child link="axle_front_left"/>
    <origin rpy="0 0 0" xyz="0.4 0 0"/>
    <axis xyz="1 0 0"/>
    <!-- <limit lower="-0.297" upper="1.038" effort="100000" velocity="0.034906585"/> -->
    <limit effort="1200000" lower="0" upper="0.01" velocity="0.2"/>
    <dynamics damping="0.7"/>
  </joint>
  <joint name="steering_angle_front_left" type="revolute">
    <parent link="axle_front_left"/>
    <child link="hub_front_left"/>
    <origin rpy="1.570796 0 0" xyz="2.04302 0.355 0.0"/>
    <!-- this 2.o will be prismatic joint cylinder -->
    <axis xyz="0 0 1"/>
    <limit effort="12000" lower="-1.672665" upper="1.6797932658" velocity="0.204906585"/>
    <dynamics damping="300.7" friction="400.0"/>
  </joint>
  <joint name="hub_tilt_joint_front_left" type="revolute">
    <parent link="hub_front_left"/>
    <child link="hub_tilt_front_left"/>
    <origin rpy="0.1 0 0" xyz="0 0.0 0.0"/>
    <!-- this 2.o will be prismatic joint cylinder -->
    <axis xyz="0 1 0"/>
    <limit effort="12000" lower="-0.102665" upper="0.1097932658" velocity="0.204906585"/>
    <dynamics damping="300.7" friction="400.0"/>
  </joint>
  <joint name="wheel_drive_front_left" type="continuous">
    <parent link="hub_tilt_front_left"/>
    <child link="wheel_front_left"/>
    <origin rpy="0 -1.570796 0" xyz="0.33 0 0"/>
    <axis xyz="0 0 1"/>
    <limit effort="1200000" velocity="1.570796327"/>
  </joint>
  <!--  <joint name="force_torque_sensor_${limb_name}" type="fixed">
     	<parent link="hub_${limb_name}"/>
     	<child link="wheel_${limb_name}"/>	
     	<origin xyz="0.1 0 0" rpy="0 0 0"/>
     	<axis xyz="0 0 1"/>
  	<limit upper="6.28" lower="-6.28" effort="1000" velocity="1000.00"/>
  	<joint_properties damping="0.1" friction="0.80" />
     	<sensor name="force_torque" type="force_torque">
          <update_rate>30</update_rate>
        </sensor>
    </joint>   -->
  <gazebo reference="hub_tilt_joint_front_left">
    <provideFeedback>true</provideFeedback>
  </gazebo>
  <gazebo>
    <plugin filename="libgazebo_ros_ft_sensor.so" name="ft_sensor">
      <updateRate>30.0</updateRate>
      <topicName>front_left/ft_sensor_topic</topicName>
      <jointName>hub_tilt_joint_front_left</jointName>
      <noise>
        <type>gaussian</type>
        <mean>0.0</mean>
        <stddev>0.003</stddev>
      </noise>
      <!--change this to simulate noise -->
    </plugin>
  </gazebo>
  <gazebo reference="wheel_front_left">
    <material>Gazebo/Black</material>
  </gazebo>
  <gazebo reference="hub_tilt_front_left">
    <material>Gazebo/Yellow</material>
  </gazebo>
  <gazebo reference="swivel_base_front_left">
    <material>Gazebo/Green</material>
  </gazebo>
  <gazebo reference="axle_front_left">
    <material>Gazebo/Orange</material>
  </gazebo>
  <!-- Links -->
  <link name="stabilizer_cylinder_front_right">
    <inertial>
      <origin rpy="0 0 0" xyz="0.05 0 0"/>
      <mass value="100.0"/>
      <inertia ixx="6.0061849" ixy="0.0" ixz="0.000" iyy="6.0061849" iyz="0.000" izz="6.0034656"/>
    </inertial>
    <visual>
      <material name="Black"/>
      <origin rpy="0 0 0" xyz="0 0 0"/>
      <geometry>
        <mesh filename="package://sherpa_tt_urdf/meshes/leg/steeringPivot.stl" scale="0.001 0.001 0.002"/>
      </geometry>
    </visual>
    <collision>
      <material name="Red"/>
      <origin rpy="0 0 0" xyz="0 0 -0.05"/>
      <geometry>
        <cylinder length="0.25" radius="0.08"/>
      </geometry>
    </collision>
  </link>
  <link name="swivel_base_front_right">
    <inertial>
      <origin rpy="0 0 0" xyz="0.2 0 0"/>
      <mass value="100.0"/>
      <inertia ixx="5.0034482759" ixy="0.00" ixz="0.000" iyy="5.0172413793" iyz="0.00" izz="5.0172413793"/>
    </inertial>
    <visual>
      <material name="Yellow"/>
      <origin rpy="0 0 0" xyz="0 0 0"/>
      <geometry>
        <mesh filename="package://sherpa_tt_urdf/meshes/leg/innerStrut.stl" scale="0.0009 0.006 0.002"/>
      </geometry>
    </visual>
    <collision>
      <material name="Red"/>
      <origin rpy="0 0 0" xyz="0.2 0 0.0"/>
      <geometry>
        <box size="0.50 0.15 0.15"/>
      </geometry>
    </collision>
  </link>
  <link name="axle_front_right">
    <inertial>
      <origin rpy="0 0 0" xyz="0 0 0"/>
      <mass value="320.0"/>
      <inertia ixx="249.0103626943" ixy="1.0004710316" ixz="0.0014130947" iyy="249.0122468205" iyz="0" izz="19.2028261894"/>
    </inertial>
    <visual>
      <material name="Black"/>
      <origin rpy="0 0 0" xyz="0 0 0"/>
      <geometry>
        <mesh filename="package://sherpa_tt_urdf/meshes/leg/outerStrut.stl" scale="0.0041 0.004 0.004"/>
      </geometry>
    </visual>
    <!--collision>
            <material name="Red"/>
            <origin xyz="0.15 0.0 0.08" rpy="0 0 0"/>
            <geometry>               
                <box size="0.06 0.14 0.4"/>
            </geometry>
        </collision-->
  </link>
  <link name="hub_front_right">
    <inertial>
      <origin rpy="0 0 0" xyz="0.2 0 0"/>
      <mass value="180.0"/>
      <inertia ixx="15.0008748906" ixy="0.0008748906" ixz="0.0" iyy="24.6157480315" iyz="0.0" izz="20.6148731409"/>
    </inertial>
    <visual>
      <material name="Yellow"/>
      <origin rpy="0 -1.6 0" xyz="0 0 -0.3"/>
      <geometry>
        <mesh filename="package://sherpa_tt_urdf/meshes/leg/driveUnit.stl" scale="0.002 0.002 0.002"/>
      </geometry>
    </visual>
    <!--collision>
                <material name="Red"/>
                <origin xyz="0.2 0 0.0" rpy="0 0 0"/>
                <geometry>               
                                     <box size="0.50 0.05 0.1"/>
                </geometry>
            </collision-->
  </link>
  <!-- -->
  <link name="hub_tilt_front_right">
    <inertial>
      <origin rpy="0 0 0" xyz="0.2 0 0"/>
      <mass value="10.0"/>
      <inertia ixx="15.0008748906" ixy="0.0008748906" ixz="0.0" iyy="24.6157480315" iyz="0.0" izz="20.6148731409"/>
    </inertial>
    <visual>
      <material name="Yellow"/>
      <origin rpy="0 0 0" xyz="0 0 0"/>
      <geometry>
        <box size="0.50 0.15 0.15"/>
      </geometry>
    </visual>
    <collision>
      <material name="Red"/>
      <origin rpy="0 0 0" xyz="0.2 0 0.0"/>
      <geometry>
        <box size="0.50 0.05 0.1"/>
      </geometry>
    </collision>
  </link>
  <link name="wheel_front_right">
    <inertial>
      <origin rpy="0 0 0" xyz="0 0 0"/>
      <mass value="280.0"/>
      <inertia ixx="105.012" ixy="0" ixz="0" iyy="105.015" iyz="0" izz="215.021"/>
    </inertial>
    <visual>
      <material name="Black"/>
      <origin rpy="0 0 0" xyz="0 0 0"/>
      <geometry>
        <mesh filename="package://walking_excavator_urdf/xacro_manzi/wheel4.stl" scale="0.35 0.35 0.35"/>
      </geometry>
    </visual>
    <collision>
      <material name="Red"/>
      <origin rpy="0 0 0" xyz="0 0 -0.03 "/>
      <geometry>
        <cylinder length="0.405" radius="0.62"/>
      </geometry>
    </collision>
  </link>
  <!--    <link name="wheel_end_point_link_${limb_name}">
            <inertial>
                <origin xyz="0 0 0" rpy="0 0 0"/>
                <mass value="0.01"/>
                <inertia ixx="0.0001" ixy="0" ixz="0" iyy="0.0001" iyz="0" izz="0.0001"/>
            </inertial>      
            <geometry>      
                <box size="0.01 0.01 0.01"/>     
            </geometry>
        </link>  

        <link name="force_torque_sensor_link_${limb_name}">
            <inertial>
                <origin xyz="0 0 0.0" rpy="0 0 0"/>
                <mass value="0.001"/>
                <inertia ixx="0.001" ixy="0" ixz="0" iyy="0" iyz="0" izz="0"/>
            </inertial>
        </link>            -->
  <!-- Joint -->
  <joint name="stabilizer_angle_front_right" type="revolute">
    <parent link="body"/>
    <child link="stabilizer_cylinder_front_right"/>
    <origin rpy="0 0 -0.7854" xyz="0.8 -0.8 0"/>
    <axis xyz="0 0 0"/>
    <limit effort="1200000" lower="-.5707963268" upper="0.581661565" velocity="0.3272664626"/>
    <dynamics damping="300.7" friction="400.0"/>
  </joint>
  <joint name="swivel_angle_front_right" type="revolute">
    <parent link="stabilizer_cylinder_front_right"/>
    <child link="swivel_base_front_right"/>
    <origin rpy="-1.570796 0.15 0" xyz="0.1375 0 0"/>
    <axis xyz="0 0 1"/>
    <limit effort="1200000" lower="-0.872664626" upper="0.4967059728" velocity="0.134906585"/>
    <dynamics damping="300.7" friction="400.0"/>
  </joint>
  <joint name="adjustment_leg_length_front_right" type="prismatic">
    <parent link="swivel_base_front_right"/>
    <child link="axle_front_right"/>
    <origin rpy="0 0 0" xyz="0.4 0 0"/>
    <axis xyz="1 0 0"/>
    <!-- <limit lower="-0.297" upper="1.038" effort="100000" velocity="0.034906585"/> -->
    <limit effort="1200000" lower="0" upper="0.01" velocity="0.2"/>
    <dynamics damping="0.7"/>
  </joint>
  <joint name="steering_angle_front_right" type="revolute">
    <parent link="axle_front_right"/>
    <child link="hub_front_right"/>
    <origin rpy="1.570796 0 0" xyz="2.04302 0.355 0.0"/>
    <!-- this 2.o will be prismatic joint cylinder -->
    <axis xyz="0 0 1"/>
    <limit effort="12000" lower="-1.672665" upper="1.6797932658" velocity="0.204906585"/>
    <dynamics damping="300.7" friction="400.0"/>
  </joint>
  <joint name="hub_tilt_joint_front_right" type="revolute">
    <parent link="hub_front_right"/>
    <child link="hub_tilt_front_right"/>
    <origin rpy="0.1 0 0" xyz="0 0.0 0.0"/>
    <!-- this 2.o will be prismatic joint cylinder -->
    <axis xyz="0 1 0"/>
    <limit effort="12000" lower="-0.102665" upper="0.1097932658" velocity="0.204906585"/>
    <dynamics damping="300.7" friction="400.0"/>
  </joint>
  <joint name="wheel_drive_front_right" type="continuous">
    <parent link="hub_tilt_front_right"/>
    <child link="wheel_front_right"/>
    <origin rpy="0 -1.570796 0" xyz="0.33 0 0"/>
    <axis xyz="0 0 1"/>
    <limit effort="1200000" velocity="1.570796327"/>
  </joint>
  <!--  <joint name="force_torque_sensor_${limb_name}" type="fixed">
     	<parent link="hub_${limb_name}"/>
     	<child link="wheel_${limb_name}"/>	
     	<origin xyz="0.1 0 0" rpy="0 0 0"/>
     	<axis xyz="0 0 1"/>
  	<limit upper="6.28" lower="-6.28" effort="1000" velocity="1000.00"/>
  	<joint_properties damping="0.1" friction="0.80" />
     	<sensor name="force_torque" type="force_torque">
          <update_rate>30</update_rate>
        </sensor>
    </joint>   -->
  <gazebo reference="hub_tilt_joint_front_right">
    <provideFeedback>true</provideFeedback>
  </gazebo>
  <gazebo>
    <plugin filename="libgazebo_ros_ft_sensor.so" name="ft_sensor">
      <updateRate>30.0</updateRate>
      <topicName>front_right/ft_sensor_topic</topicName>
      <jointName>hub_tilt_joint_front_right</jointName>
      <noise>
        <type>gaussian</type>
        <mean>0.0</mean>
        <stddev>0.003</stddev>
      </noise>
      <!--change this to simulate noise -->
    </plugin>
  </gazebo>
  <gazebo reference="wheel_front_right">
    <material>Gazebo/Black</material>
  </gazebo>
  <gazebo reference="hub_tilt_front_right">
    <material>Gazebo/Yellow</material>
  </gazebo>
  <gazebo reference="swivel_base_front_right">
    <material>Gazebo/Green</material>
  </gazebo>
  <gazebo reference="axle_front_right">
    <material>Gazebo/Orange</material>
  </gazebo>
  <!-- Links -->
  <link name="stabilizer_cylinder_rear_left">
    <inertial>
      <origin rpy="0 0 0" xyz="0.05 0 0"/>
      <mass value="100.0"/>
      <inertia ixx="6.0061849" ixy="0.0" ixz="0.000" iyy="6.0061849" iyz="0.000" izz="6.0034656"/>
    </inertial>
    <visual>
      <material name="Black"/>
      <origin rpy="0 0 0" xyz="0 0 0"/>
      <geometry>
        <mesh filename="package://sherpa_tt_urdf/meshes/leg/steeringPivot.stl" scale="0.001 0.001 0.002"/>
      </geometry>
    </visual>
    <collision>
      <material name="Red"/>
      <origin rpy="0 0 0" xyz="0 0 -0.05"/>
      <geometry>
        <cylinder length="0.25" radius="0.08"/>
      </geometry>
    </collision>
  </link>
  <link name="swivel_base_rear_left">
    <inertial>
      <origin rpy="0 0 0" xyz="0.2 0 0"/>
      <mass value="100.0"/>
      <inertia ixx="5.0034482759" ixy="0.00" ixz="0.000" iyy="5.0172413793" iyz="0.00" izz="5.0172413793"/>
    </inertial>
    <visual>
      <material name="Yellow"/>
      <origin rpy="0 0 0" xyz="0 0 0"/>
      <geometry>
        <mesh filename="package://sherpa_tt_urdf/meshes/leg/innerStrut.stl" scale="0.0009 0.006 0.002"/>
      </geometry>
    </visual>
    <collision>
      <material name="Red"/>
      <origin rpy="0 0 0" xyz="0.2 0 0.0"/>
      <geometry>
        <box size="0.50 0.15 0.15"/>
      </geometry>
    </collision>
  </link>
  <link name="axle_rear_left">
    <inertial>
      <origin rpy="0 0 0" xyz="0 0 0"/>
      <mass value="320.0"/>
      <inertia ixx="249.0103626943" ixy="1.0004710316" ixz="0.0014130947" iyy="249.0122468205" iyz="0" izz="19.2028261894"/>
    </inertial>
    <visual>
      <material name="Black"/>
      <origin rpy="0 0 0" xyz="0 0 0"/>
      <geometry>
        <mesh filename="package://sherpa_tt_urdf/meshes/leg/outerStrut.stl" scale="0.0041 0.004 0.004"/>
      </geometry>
    </visual>
    <!--collision>
            <material name="Red"/>
            <origin xyz="0.15 0.0 0.08" rpy="0 0 0"/>
            <geometry>               
                <box size="0.06 0.14 0.4"/>
            </geometry>
        </collision-->
  </link>
  <link name="hub_rear_left">
    <inertial>
      <origin rpy="0 0 0" xyz="0.2 0 0"/>
      <mass value="180.0"/>
      <inertia ixx="15.0008748906" ixy="0.0008748906" ixz="0.0" iyy="24.6157480315" iyz="0.0" izz="20.6148731409"/>
    </inertial>
    <visual>
      <material name="Yellow"/>
      <origin rpy="0 -1.6 0" xyz="0 0 -0.3"/>
      <geometry>
        <mesh filename="package://sherpa_tt_urdf/meshes/leg/driveUnit.stl" scale="0.002 0.002 0.002"/>
      </geometry>
    </visual>
    <!--collision>
                <material name="Red"/>
                <origin xyz="0.2 0 0.0" rpy="0 0 0"/>
                <geometry>               
                                     <box size="0.50 0.05 0.1"/>
                </geometry>
            </collision-->
  </link>
  <!-- -->
  <link name="hub_tilt_rear_left">
    <inertial>
      <origin rpy="0 0 0" xyz="0.2 0 0"/>
      <mass value="10.0"/>
      <inertia ixx="15.0008748906" ixy="0.0008748906" ixz="0.0" iyy="24.6157480315" iyz="0.0" izz="20.6148731409"/>
    </inertial>
    <visual>
      <material name="Yellow"/>
      <origin rpy="0 0 0" xyz="0 0 0"/>
      <geometry>
        <box size="0.50 0.15 0.15"/>
      </geometry>
    </visual>
    <collision>
      <material name="Red"/>
      <origin rpy="0 0 0" xyz="0.2 0 0.0"/>
      <geometry>
        <box size="0.50 0.05 0.1"/>
      </geometry>
    </collision>
  </link>
  <link name="wheel_rear_left">
    <inertial>
      <origin rpy="0 0 0" xyz="0 0 0"/>
      <mass value="280.0"/>
      <inertia ixx="105.012" ixy="0" ixz="0" iyy="105.015" iyz="0" izz="215.021"/>
    </inertial>
    <visual>
      <material name="Black"/>
      <origin rpy="0 0 0" xyz="0 0 0"/>
      <geometry>
        <mesh filename="package://walking_excavator_urdf/xacro_manzi/wheel4.stl" scale="0.35 0.35 0.35"/>
      </geometry>
    </visual>
    <collision>
      <material name="Red"/>
      <origin rpy="0 0 0" xyz="0 0 -0.03 "/>
      <geometry>
        <cylinder length="0.405" radius="0.62"/>
      </geometry>
    </collision>
  </link>
  <!--    <link name="wheel_end_point_link_${limb_name}">
            <inertial>
                <origin xyz="0 0 0" rpy="0 0 0"/>
                <mass value="0.01"/>
                <inertia ixx="0.0001" ixy="0" ixz="0" iyy="0.0001" iyz="0" izz="0.0001"/>
            </inertial>      
            <geometry>      
                <box size="0.01 0.01 0.01"/>     
            </geometry>
        </link>  

        <link name="force_torque_sensor_link_${limb_name}">
            <inertial>
                <origin xyz="0 0 0.0" rpy="0 0 0"/>
                <mass value="0.001"/>
                <inertia ixx="0.001" ixy="0" ixz="0" iyy="0" iyz="0" izz="0"/>
            </inertial>
        </link>            -->
  <!-- Joint -->
  <joint name="stabilizer_angle_rear_left" type="revolute">
    <parent link="body"/>
    <child link="stabilizer_cylinder_rear_left"/>
    <origin rpy="0 0 2.356194" xyz="-0.8 0.8 0"/>
    <axis xyz="0 0 0"/>
    <limit effort="1200000" lower="-.5707963268" upper="0.581661565" velocity="0.3272664626"/>
    <dynamics damping="300.7" friction="400.0"/>
  </joint>
  <joint name="swivel_angle_rear_left" type="revolute">
    <parent link="stabilizer_cylinder_rear_left"/>
    <child link="swivel_base_rear_left"/>
    <origin rpy="-1.570796 0.15 0" xyz="0.1375 0 0"/>
    <axis xyz="0 0 1"/>
    <limit effort="1200000" lower="-0.872664626" upper="0.4967059728" velocity="0.134906585"/>
    <dynamics damping="300.7" friction="400.0"/>
  </joint>
  <joint name="adjustment_leg_length_rear_left" type="prismatic">
    <parent link="swivel_base_rear_left"/>
    <child link="axle_rear_left"/>
    <origin rpy="0 0 0" xyz="0.4 0 0"/>
    <axis xyz="1 0 0"/>
    <!-- <limit lower="-0.297" upper="1.038" effort="100000" velocity="0.034906585"/> -->
    <limit effort="1200000" lower="0" upper="0.01" velocity="0.2"/>
    <dynamics damping="0.7"/>
  </joint>
  <joint name="steering_angle_rear_left" type="revolute">
    <parent link="axle_rear_left"/>
    <child link="hub_rear_left"/>
    <origin rpy="1.570796 0 0" xyz="2.04302 0.355 0.0"/>
    <!-- this 2.o will be prismatic joint cylinder -->
    <axis xyz="0 0 1"/>
    <limit effort="12000" lower="-1.672665" upper="1.6797932658" velocity="0.204906585"/>
    <dynamics damping="300.7" friction="400.0"/>
  </joint>
  <joint name="hub_tilt_joint_rear_left" type="revolute">
    <parent link="hub_rear_left"/>
    <child link="hub_tilt_rear_left"/>
    <origin rpy="0.1 0 0" xyz="0 0.0 0.0"/>
    <!-- this 2.o will be prismatic joint cylinder -->
    <axis xyz="0 1 0"/>
    <limit effort="12000" lower="-0.102665" upper="0.1097932658" velocity="0.204906585"/>
    <dynamics damping="300.7" friction="400.0"/>
  </joint>
  <joint name="wheel_drive_rear_left" type="continuous">
    <parent link="hub_tilt_rear_left"/>
    <child link="wheel_rear_left"/>
    <origin rpy="0 -1.570796 0" xyz="0.33 0 0"/>
    <axis xyz="0 0 1"/>
    <limit effort="1200000" velocity="1.570796327"/>
  </joint>
  <!--  <joint name="force_torque_sensor_${limb_name}" type="fixed">
     	<parent link="hub_${limb_name}"/>
     	<child link="wheel_${limb_name}"/>	
     	<origin xyz="0.1 0 0" rpy="0 0 0"/>
     	<axis xyz="0 0 1"/>
  	<limit upper="6.28" lower="-6.28" effort="1000" velocity="1000.00"/>
  	<joint_properties damping="0.1" friction="0.80" />
     	<sensor name="force_torque" type="force_torque">
          <update_rate>30</update_rate>
        </sensor>
    </joint>   -->
  <gazebo reference="hub_tilt_joint_rear_left">
    <provideFeedback>true</provideFeedback>
  </gazebo>
  <gazebo>
    <plugin filename="libgazebo_ros_ft_sensor.so" name="ft_sensor">
      <updateRate>30.0</updateRate>
      <topicName>rear_left/ft_sensor_topic</topicName>
      <jointName>hub_tilt_joint_rear_left</jointName>
      <noise>
        <type>gaussian</type>
        <mean>0.0</mean>
        <stddev>0.003</stddev>
      </noise>
      <!--change this to simulate noise -->
    </plugin>
  </gazebo>
  <gazebo reference="wheel_rear_left">
    <material>Gazebo/Black</material>
  </gazebo>
  <gazebo reference="hub_tilt_rear_left">
    <material>Gazebo/Yellow</material>
  </gazebo>
  <gazebo reference="swivel_base_rear_left">
    <material>Gazebo/Green</material>
  </gazebo>
  <gazebo reference="axle_rear_left">
    <material>Gazebo/Orange</material>
  </gazebo>
  <!-- Links -->
  <link name="stabilizer_cylinder_rear_right">
    <inertial>
      <origin rpy="0 0 0" xyz="0.05 0 0"/>
      <mass value="100.0"/>
      <inertia ixx="6.0061849" ixy="0.0" ixz="0.000" iyy="6.0061849" iyz="0.000" izz="6.0034656"/>
    </inertial>
    <visual>
      <material name="Black"/>
      <origin rpy="0 0 0" xyz="0 0 0"/>
      <geometry>
        <mesh filename="package://sherpa_tt_urdf/meshes/leg/steeringPivot.stl" scale="0.001 0.001 0.002"/>
      </geometry>
    </visual>
    <collision>
      <material name="Red"/>
      <origin rpy="0 0 0" xyz="0 0 -0.05"/>
      <geometry>
        <cylinder length="0.25" radius="0.08"/>
      </geometry>
    </collision>
  </link>
  <link name="swivel_base_rear_right">
    <inertial>
      <origin rpy="0 0 0" xyz="0.2 0 0"/>
      <mass value="100.0"/>
      <inertia ixx="5.0034482759" ixy="0.00" ixz="0.000" iyy="5.0172413793" iyz="0.00" izz="5.0172413793"/>
    </inertial>
    <visual>
      <material name="Yellow"/>
      <origin rpy="0 0 0" xyz="0 0 0"/>
      <geometry>
        <mesh filename="package://sherpa_tt_urdf/meshes/leg/innerStrut.stl" scale="0.0009 0.006 0.002"/>
      </geometry>
    </visual>
    <collision>
      <material name="Red"/>
      <origin rpy="0 0 0" xyz="0.2 0 0.0"/>
      <geometry>
        <box size="0.50 0.15 0.15"/>
      </geometry>
    </collision>
  </link>
  <link name="axle_rear_right">
    <inertial>
      <origin rpy="0 0 0" xyz="0 0 0"/>
      <mass value="320.0"/>
      <inertia ixx="249.0103626943" ixy="1.0004710316" ixz="0.0014130947" iyy="249.0122468205" iyz="0" izz="19.2028261894"/>
    </inertial>
    <visual>
      <material name="Black"/>
      <origin rpy="0 0 0" xyz="0 0 0"/>
      <geometry>
        <mesh filename="package://sherpa_tt_urdf/meshes/leg/outerStrut.stl" scale="0.0041 0.004 0.004"/>
      </geometry>
    </visual>
    <!--collision>
            <material name="Red"/>
            <origin xyz="0.15 0.0 0.08" rpy="0 0 0"/>
            <geometry>               
                <box size="0.06 0.14 0.4"/>
            </geometry>
        </collision-->
  </link>
  <link name="hub_rear_right">
    <inertial>
      <origin rpy="0 0 0" xyz="0.2 0 0"/>
      <mass value="180.0"/>
      <inertia ixx="15.0008748906" ixy="0.0008748906" ixz="0.0" iyy="24.6157480315" iyz="0.0" izz="20.6148731409"/>
    </inertial>
    <visual>
      <material name="Yellow"/>
      <origin rpy="0 -1.6 0" xyz="0 0 -0.3"/>
      <geometry>
        <mesh filename="package://sherpa_tt_urdf/meshes/leg/driveUnit.stl" scale="0.002 0.002 0.002"/>
      </geometry>
    </visual>
    <!--collision>
                <material name="Red"/>
                <origin xyz="0.2 0 0.0" rpy="0 0 0"/>
                <geometry>               
                                     <box size="0.50 0.05 0.1"/>
                </geometry>
            </collision-->
  </link>
  <!-- -->
  <link name="hub_tilt_rear_right">
    <inertial>
      <origin rpy="0 0 0" xyz="0.2 0 0"/>
      <mass value="10.0"/>
      <inertia ixx="15.0008748906" ixy="0.0008748906" ixz="0.0" iyy="24.6157480315" iyz="0.0" izz="20.6148731409"/>
    </inertial>
    <visual>
      <material name="Yellow"/>
      <origin rpy="0 0 0" xyz="0 0 0"/>
      <geometry>
        <box size="0.50 0.15 0.15"/>
      </geometry>
    </visual>
    <collision>
      <material name="Red"/>
      <origin rpy="0 0 0" xyz="0.2 0 0.0"/>
      <geometry>
        <box size="0.50 0.05 0.1"/>
      </geometry>
    </collision>
  </link>
  <link name="wheel_rear_right">
    <inertial>
      <origin rpy="0 0 0" xyz="0 0 0"/>
      <mass value="280.0"/>
      <inertia ixx="105.012" ixy="0" ixz="0" iyy="105.015" iyz="0" izz="215.021"/>
    </inertial>
    <visual>
      <material name="Black"/>
      <origin rpy="0 0 0" xyz="0 0 0"/>
      <geometry>
        <mesh filename="package://walking_excavator_urdf/xacro_manzi/wheel4.stl" scale="0.35 0.35 0.35"/>
      </geometry>
    </visual>
    <collision>
      <material name="Red"/>
      <origin rpy="0 0 0" xyz="0 0 -0.03 "/>
      <geometry>
        <cylinder length="0.405" radius="0.62"/>
      </geometry>
    </collision>
  </link>
  <!--    <link name="wheel_end_point_link_${limb_name}">
            <inertial>
                <origin xyz="0 0 0" rpy="0 0 0"/>
                <mass value="0.01"/>
                <inertia ixx="0.0001" ixy="0" ixz="0" iyy="0.0001" iyz="0" izz="0.0001"/>
            </inertial>      
            <geometry>      
                <box size="0.01 0.01 0.01"/>     
            </geometry>
        </link>  

        <link name="force_torque_sensor_link_${limb_name}">
            <inertial>
                <origin xyz="0 0 0.0" rpy="0 0 0"/>
                <mass value="0.001"/>
                <inertia ixx="0.001" ixy="0" ixz="0" iyy="0" iyz="0" izz="0"/>
            </inertial>
        </link>            -->
  <!-- Joint -->
  <joint name="stabilizer_angle_rear_right" type="revolute">
    <parent link="body"/>
    <child link="stabilizer_cylinder_rear_right"/>
    <origin rpy="0 0 -2.356194" xyz="-0.8 -0.8 0"/>
    <axis xyz="0 0 0"/>
    <limit effort="1200000" lower="-.5707963268" upper="0.581661565" velocity="0.3272664626"/>
    <dynamics damping="300.7" friction="400.0"/>
  </joint>
  <joint name="swivel_angle_rear_right" type="revolute">
    <parent link="stabilizer_cylinder_rear_right"/>
    <child link="swivel_base_rear_right"/>
    <origin rpy="-1.570796 0.15 0" xyz="0.1375 0 0"/>
    <axis xyz="0 0 1"/>
    <limit effort="1200000" lower="-0.872664626" upper="0.4967059728" velocity="0.134906585"/>
    <dynamics damping="300.7" friction="400.0"/>
  </joint>
  <joint name="adjustment_leg_length_rear_right" type="prismatic">
    <parent link="swivel_base_rear_right"/>
    <child link="axle_rear_right"/>
    <origin rpy="0 0 0" xyz="0.4 0 0"/>
    <axis xyz="1 0 0"/>
    <!-- <limit lower="-0.297" upper="1.038" effort="100000" velocity="0.034906585"/> -->
    <limit effort="1200000" lower="0" upper="0.01" velocity="0.2"/>
    <dynamics damping="0.7"/>
  </joint>
  <joint name="steering_angle_rear_right" type="revolute">
    <parent link="axle_rear_right"/>
    <child link="hub_rear_right"/>
    <origin rpy="1.570796 0 0" xyz="2.04302 0.355 0.0"/>
    <!-- this 2.o will be prismatic joint cylinder -->
    <axis xyz="0 0 1"/>
    <limit effort="12000" lower="-1.672665" upper="1.6797932658" velocity="0.204906585"/>
    <dynamics damping="300.7" friction="400.0"/>
  </joint>
  <joint name="hub_tilt_joint_rear_right" type="revolute">
    <parent link="hub_rear_right"/>
    <child link="hub_tilt_rear_right"/>
    <origin rpy="0.1 0 0" xyz="0 0.0 0.0"/>
    <!-- this 2.o will be prismatic joint cylinder -->
    <axis xyz="0 1 0"/>
    <limit effort="12000" lower="-0.102665" upper="0.1097932658" velocity="0.204906585"/>
    <dynamics damping="300.7" friction="400.0"/>
  </joint>
  <joint name="wheel_drive_rear_right" type="continuous">
    <parent link="hub_tilt_rear_right"/>
    <child link="wheel_rear_right"/>
    <origin rpy="0 -1.570796 0" xyz="0.33 0 0"/>
    <axis xyz="0 0 1"/>
    <limit effort="1200000" velocity="1.570796327"/>
  </joint>
  <!--  <joint name="force_torque_sensor_${limb_name}" type="fixed">
     	<parent link="hub_${limb_name}"/>
     	<child link="wheel_${limb_name}"/>	
     	<origin xyz="0.1 0 0" rpy="0 0 0"/>
     	<axis xyz="0 0 1"/>
  	<limit upper="6.28" lower="-6.28" effort="1000" velocity="1000.00"/>
  	<joint_properties damping="0.1" friction="0.80" />
     	<sensor name="force_torque" type="force_torque">
          <update_rate>30</update_rate>
        </sensor>
    </joint>   -->
  <gazebo reference="hub_tilt_joint_rear_right">
    <provideFeedback>true</provideFeedback>
  </gazebo>
  <gazebo>
    <plugin filename="libgazebo_ros_ft_sensor.so" name="ft_sensor">
      <updateRate>30.0</updateRate>
      <topicName>rear_right/ft_sensor_topic</topicName>
      <jointName>hub_tilt_joint_rear_right</jointName>
      <noise>
        <type>gaussian</type>
        <mean>0.0</mean>
        <stddev>0.003</stddev>
      </noise>
      <!--change this to simulate noise -->
    </plugin>
  </gazebo>
  <gazebo reference="wheel_rear_right">
    <material>Gazebo/Black</material>
  </gazebo>
  <gazebo reference="hub_tilt_rear_right">
    <material>Gazebo/Yellow</material>
  </gazebo>
  <gazebo reference="swivel_base_rear_right">
    <material>Gazebo/Green</material>
  </gazebo>
  <gazebo reference="axle_rear_right">
    <material>Gazebo/Orange</material>
  </gazebo>
  <!-- Arm joints -->
  <joint name="boom_body_base_joint" type="revolute">
    <parent link="cab"/>
    <child link="boom_link1"/>
    <origin rpy="0 -1.0 0" xyz="0.6 0.6 -1.0"/>
    <axis xyz="0 1 0"/>
    <limit effort="1200000" lower="-0.4" upper="+1.0" velocity="0.1415926535897931"/>
    <dynamics damping="30000.7" friction="40000.0"/>
  </joint>
  <link name="boom_link1">
    <inertial>
      <origin rpy="0 0 0" xyz="0 0 0"/>
      <mass value="720.1"/>
      <!-- 14.1 -->
      <inertia ixx="1692.6" ixy="0.000382827" ixz="0.0010607499" iyy="1692.6" iyz="0.1148162032" izz="14.4"/>
    </inertial>
    <visual>
      <material name="Orange"/>
      <origin rpy="0 0 0" xyz="0 0 0.0"/>
      <geometry>
        <mesh filename="package://walking_excavator_urdf/xacro_manzi/body_boom_leg11.stl" scale="1 1 1"/>
      </geometry>
    </visual>
    <collision>
      <material name="Red"/>
      <origin rpy="0 0 0" xyz="0.0 0.0 0.0"/>
      <geometry>
        <box size="0.3 0.85 0.1"/>
      </geometry>
    </collision>
  </link>
  <joint name="boom_joint1" type="revolute">
    <parent link="boom_link1"/>
    <child link="boom_link2"/>
    <origin rpy="0 1.5 0" xyz="5.3 0 2.8"/>
    <axis xyz="0 1 0"/>
    <limit effort="1200000" lower="-0.45432" upper="+0.45432" velocity="0.2415926535897931"/>
    <dynamics damping="300.7" friction="400.0"/>
  </joint>
  <link name="boom_link2">
    <inertial>
      <origin rpy="0 0 0" xyz="0 0 0"/>
      <mass value="850.1"/>
      <!-- 14.1 -->
      <inertia ixx="5.01" ixy="0.000382827" ixz="0.0010607499" iyy="5.666667" iyz="0.1148162032" izz="5.666667"/>
    </inertial>
    <visual>
      <material name="Orange"/>
      <origin rpy="0 0 0" xyz="0 0 0"/>
      <geometry>
        <mesh filename="package://walking_excavator_urdf/xacro_manzi/body_boom_leg2.stl" scale="1 0.5 1"/>
      </geometry>
    </visual>
    <collision>
      <material name="Red"/>
      <origin rpy="0 0 0" xyz="0.0 0.0 0.0"/>
      <geometry>
        <box size="0.3 0.85 0.1"/>
      </geometry>
    </collision>
  </link>
  <joint name="boom_transalation_joint" type="prismatic">
    <parent link="boom_link2"/>
    <child link="boom_link3"/>
    <origin rpy="0 0 0" xyz="3.3 0 0.08"/>
    <axis xyz="1 0 0"/>
    <limit effort="2200000" lower="-0.15432" upper="+2.45432" velocity="0.1415926535897931"/>
    <dynamics damping="30000.7" friction="4000.0"/>
  </joint>
  <link name="boom_link3">
    <inertial>
      <origin rpy="0 0 0" xyz="0 0 0"/>
      <mass value="100.1"/>
      <!-- 14.1 -->
      <inertia ixx="5.01" ixy="0.000382827" ixz="0.0010607499" iyy="5.666667" iyz="0.1148162032" izz="5.666667"/>
    </inertial>
    <visual>
      <origin rpy="0 0 0" xyz="0 0 0"/>
      <geometry>
        <box size="2.3 0.25 0.33"/>
      </geometry>
    </visual>
    <collision>
      <material name="Red"/>
      <origin rpy="0 0 0" xyz="0.0 0.0 0.0"/>
      <geometry>
        <box size="1.3 0.25 0.23"/>
      </geometry>
    </collision>
  </link>
  <joint name="boom_bucket_joint" type="revolute">
    <parent link="boom_link3"/>
    <child link="bucket"/>
    <origin rpy="0 0 0" xyz="0.88 0 0.1"/>
    <!-- 0 1.5 0 -->
    <axis xyz="0 1 0"/>
    <limit effort="1200000" lower="-0.55432" upper="+0.55432" velocity="0.1415926535897931"/>
    <dynamics damping="3000.7" friction="400.0"/>
  </joint>
  <link name="bucket">
    <inertial>
      <origin rpy="0 0 0" xyz="0 0 0"/>
      <mass value="210.1"/>
      <!-- 14.1 -->
      <inertia ixx="5.01" ixy="0.000382827" ixz="0.0010607499" iyy="5.666667" iyz="0.1148162032" izz="5.666667"/>
    </inertial>
    <visual>
      <material name="Orange"/>
      <origin rpy="0 0 0" xyz="0 0 0.0"/>
      <geometry>
        <mesh filename="package://walking_excavator_urdf/xacro_manzi/bucket1.stl" scale="1 1 1"/>
      </geometry>
    </visual>
    <collision>
      <material name="Red"/>
      <origin rpy="0 0 0" xyz="0.0 0.0 0.0"/>
      <geometry>
        <mesh filename="package://walking_excavator_urdf/xacro_manzi/bucket1.stl" scale="1 1 1"/>
        <!-- <box size="0.3 0.85 0.50"/>          -->
      </geometry>
    </collision>
  </link>
  <gazebo reference="boom_link3">
    <kp>100000000.0</kp>
    <kd>1.0</kd>
    <mu1>100.0</mu1>
    <mu2>100.0</mu2>
    <slip1>0.0</slip1>
    <slip2>0.0</slip2>
    <maxVel>0.0</maxVel>
    <minDepth>0.001</minDepth>
  </gazebo>
  <gazebo reference="bucket">
    <kp>100000000.0</kp>
    <kd>1.0</kd>
    <mu1>0.70</mu1>
    <mu2>0.70</mu2>
    <slip1>0.0</slip1>
    <slip2>0.0</slip2>
    <maxVel>0.0</maxVel>
    <minDepth>0.003</minDepth>
  </gazebo>
  <transmission name="t_boom_body_base_joint">
    <type>transmission_interface/SimpleTransmission</type>
    <joint name="boom_body_base_joint">
      <hardwareInterface>hardware_interface/EffortJointInterface</hardwareInterface>
    </joint>
    <actuator name="m_boom_body_base_joint">
      <hardwareInterface>hardware_interface/EffortJointInterface</hardwareInterface>
      <mechanicalReduction>1</mechanicalReduction>
    </actuator>
  </transmission>
  <transmission name="t_boom_joint1">
    <type>transmission_interface/SimpleTransmission</type>
    <joint name="boom_joint1">
      <hardwareInterface>hardware_interface/EffortJointInterface</hardwareInterface>
    </joint>
    <actuator name="m_boom_joint1">
      <hardwareInterface>hardware_interface/EffortJointInterface</hardwareInterface>
      <mechanicalReduction>1</mechanicalReduction>
    </actuator>
  </transmission>
  <transmission name="t_boom_transalation_joint">
    <type>transmission_interface/SimpleTransmission</type>
    <joint name="boom_transalation_joint">
      <hardwareInterface>hardware_interface/EffortJointInterface</hardwareInterface>
    </joint>
    <actuator name="m_boom_transalation_joint">
      <hardwareInterface>hardware_interface/EffortJointInterface</hardwareInterface>
      <mechanicalReduction>1</mechanicalReduction>
    </actuator>
  </transmission>
  <transmission name="t_stabilizer_angle_front_left">
    <type>transmission_interface/SimpleTransmission</type>
    <joint name="stabilizer_angle_front_left">
      <hardwareInterface>hardware_interface/EffortJointInterface</hardwareInterface>
    </joint>
    <actuator name="m_stabilizer_angle_front_left">
      <hardwareInterface>hardware_interface/EffortJointInterface</hardwareInterface>
      <mechanicalReduction>1</mechanicalReduction>
    </actuator>
  </transmission>
  <transmission name="t_swivel_angle_front_left">
    <type>transmission_interface/SimpleTransmission</type>
    <joint name="swivel_angle_front_left">
      <hardwareInterface>hardware_interface/EffortJointInterface</hardwareInterface>
    </joint>
    <actuator name="m_swivel_angle_front_left">
      <hardwareInterface>hardware_interface/EffortJointInterface</hardwareInterface>
      <mechanicalReduction>1</mechanicalReduction>
    </actuator>
  </transmission>
  <transmission name="t_adjustment_leg_length_front_left">
    <type>transmission_interface/SimpleTransmission</type>
    <joint name="adjustment_leg_length_front_left">
      <hardwareInterface>hardware_interface/EffortJointInterface</hardwareInterface>
    </joint>
    <actuator name="m_adjustment_leg_length_front_left">
      <hardwareInterface>hardware_interface/EffortJointInterface</hardwareInterface>
      <mechanicalReduction>1</mechanicalReduction>
    </actuator>
  </transmission>
  <transmission name="t_steering_angle_front_left">
    <type>transmission_interface/SimpleTransmission</type>
    <joint name="steering_angle_front_left">
      <hardwareInterface>hardware_interface/EffortJointInterface</hardwareInterface>
    </joint>
    <actuator name="m_steering_angle_front_left">
      <hardwareInterface>hardware_interface/EffortJointInterface</hardwareInterface>
      <mechanicalReduction>1</mechanicalReduction>
    </actuator>
  </transmission>
  <transmission name="t_wheel_drive_front_left">
    <type>transmission_interface/SimpleTransmission</type>
    <joint name="wheel_drive_front_left">
      <hardwareInterface>hardware_interface/EffortJointInterface</hardwareInterface>
    </joint>
    <actuator name="m_wheel_drive_front_left">
      <hardwareInterface>hardware_interface/EffortJointInterface</hardwareInterface>
      <mechanicalReduction>1</mechanicalReduction>
    </actuator>
  </transmission>
  <transmission name="t_stabilizer_angle_front_right">
    <type>transmission_interface/SimpleTransmission</type>
    <joint name="stabilizer_angle_front_right">
      <hardwareInterface>hardware_interface/EffortJointInterface</hardwareInterface>
    </joint>
    <actuator name="m_stabilizer_angle_front_right">
      <hardwareInterface>hardware_interface/EffortJointInterface</hardwareInterface>
      <mechanicalReduction>1</mechanicalReduction>
    </actuator>
  </transmission>
  <transmission name="t_swivel_angle_front_right">
    <type>transmission_interface/SimpleTransmission</type>
    <joint name="swivel_angle_front_right">
      <hardwareInterface>hardware_interface/EffortJointInterface</hardwareInterface>
    </joint>
    <actuator name="m_swivel_angle_front_right">
      <hardwareInterface>hardware_interface/EffortJointInterface</hardwareInterface>
      <mechanicalReduction>1</mechanicalReduction>
    </actuator>
  </transmission>
  <transmission name="t_adjustment_leg_length_front_right">
    <type>transmission_interface/SimpleTransmission</type>
    <joint name="adjustment_leg_length_front_right">
      <hardwareInterface>hardware_interface/EffortJointInterface</hardwareInterface>
    </joint>
    <actuator name="m_adjustment_leg_length_front_right">
      <hardwareInterface>hardware_interface/EffortJointInterface</hardwareInterface>
      <mechanicalReduction>1</mechanicalReduction>
    </actuator>
  </transmission>
  <transmission name="t_steering_angle_front_right">
    <type>transmission_interface/SimpleTransmission</type>
    <joint name="steering_angle_front_right">
      <hardwareInterface>hardware_interface/EffortJointInterface</hardwareInterface>
    </joint>
    <actuator name="m_steering_angle_front_right">
      <hardwareInterface>hardware_interface/EffortJointInterface</hardwareInterface>
      <mechanicalReduction>1</mechanicalReduction>
    </actuator>
  </transmission>
  <transmission name="t_wheel_drive_front_right">
    <type>transmission_interface/SimpleTransmission</type>
    <joint name="wheel_drive_front_right">
      <hardwareInterface>hardware_interface/EffortJointInterface</hardwareInterface>
    </joint>
    <actuator name="m_wheel_drive_front_right">
      <hardwareInterface>hardware_interface/EffortJointInterface</hardwareInterface>
      <mechanicalReduction>1</mechanicalReduction>
    </actuator>
  </transmission>
  <transmission name="t_stabilizer_angle_rear_left">
    <type>transmission_interface/SimpleTransmission</type>
    <joint name="stabilizer_angle_rear_left">
      <hardwareInterface>hardware_interface/EffortJointInterface</hardwareInterface>
    </joint>
    <actuator name="m_stabilizer_angle_rear_left">
      <hardwareInterface>hardware_interface/EffortJointInterface</hardwareInterface>
      <mechanicalReduction>1</mechanicalReduction>
    </actuator>
  </transmission>
  <transmission name="t_swivel_angle_rear_left">
    <type>transmission_interface/SimpleTransmission</type>
    <joint name="swivel_angle_rear_left">
      <hardwareInterface>hardware_interface/EffortJointInterface</hardwareInterface>
    </joint>
    <actuator name="m_swivel_angle_rear_left">
      <hardwareInterface>hardware_interface/EffortJointInterface</hardwareInterface>
      <mechanicalReduction>1</mechanicalReduction>
    </actuator>
  </transmission>
  <transmission name="t_adjustment_leg_length_rear_left">
    <type>transmission_interface/SimpleTransmission</type>
    <joint name="adjustment_leg_length_rear_left">
      <hardwareInterface>hardware_interface/EffortJointInterface</hardwareInterface>
    </joint>
    <actuator name="m_adjustment_leg_length_rear_left">
      <hardwareInterface>hardware_interface/EffortJointInterface</hardwareInterface>
      <mechanicalReduction>1</mechanicalReduction>
    </actuator>
  </transmission>
  <transmission name="t_steering_angle_rear_left">
    <type>transmission_interface/SimpleTransmission</type>
    <joint name="steering_angle_rear_left">
      <hardwareInterface>hardware_interface/EffortJointInterface</hardwareInterface>
    </joint>
    <actuator name="m_steering_angle_rear_left">
      <hardwareInterface>hardware_interface/EffortJointInterface</hardwareInterface>
      <mechanicalReduction>1</mechanicalReduction>
    </actuator>
  </transmission>
  <transmission name="t_wheel_drive_rear_left">
    <type>transmission_interface/SimpleTransmission</type>
    <joint name="wheel_drive_rear_left">
      <hardwareInterface>hardware_interface/EffortJointInterface</hardwareInterface>
    </joint>
    <actuator name="m_wheel_drive_rear_left">
      <hardwareInterface>hardware_interface/EffortJointInterface</hardwareInterface>
      <mechanicalReduction>1</mechanicalReduction>
    </actuator>
  </transmission>
  <transmission name="t_stabilizer_angle_rear_right">
    <type>transmission_interface/SimpleTransmission</type>
    <joint name="stabilizer_angle_rear_right">
      <hardwareInterface>hardware_interface/EffortJointInterface</hardwareInterface>
    </joint>
    <actuator name="m_stabilizer_angle_rear_right">
      <hardwareInterface>hardware_interface/EffortJointInterface</hardwareInterface>
      <mechanicalReduction>1</mechanicalReduction>
    </actuator>
  </transmission>
  <transmission name="t_swivel_angle_rear_right">
    <type>transmission_interface/SimpleTransmission</type>
    <joint name="swivel_angle_rear_right">
      <hardwareInterface>hardware_interface/EffortJointInterface</hardwareInterface>
    </joint>
    <actuator name="m_swivel_angle_rear_right">
      <hardwareInterface>hardware_interface/EffortJointInterface</hardwareInterface>
      <mechanicalReduction>1</mechanicalReduction>
    </actuator>
  </transmission>
  <transmission name="t_adjustment_leg_length_rear_right">
    <type>transmission_interface/SimpleTransmission</type>
    <joint name="adjustment_leg_length_rear_right">
      <hardwareInterface>hardware_interface/EffortJointInterface</hardwareInterface>
    </joint>
    <actuator name="m_adjustment_leg_length_rear_right">
      <hardwareInterface>hardware_interface/EffortJointInterface</hardwareInterface>
      <mechanicalReduction>1</mechanicalReduction>
    </actuator>
  </transmission>
  <transmission name="t_steering_angle_rear_right">
    <type>transmission_interface/SimpleTransmission</type>
    <joint name="steering_angle_rear_right">
      <hardwareInterface>hardware_interface/EffortJointInterface</hardwareInterface>
    </joint>
    <actuator name="m_steering_angle_rear_right">
      <hardwareInterface>hardware_interface/EffortJointInterface</hardwareInterface>
      <mechanicalReduction>1</mechanicalReduction>
    </actuator>
  </transmission>
  <transmission name="t_wheel_drive_rear_right">
    <type>transmission_interface/SimpleTransmission</type>
    <joint name="wheel_drive_rear_right">
      <hardwareInterface>hardware_interface/EffortJointInterface</hardwareInterface>
    </joint>
    <actuator name="m_wheel_drive_rear_right">
      <hardwareInterface>hardware_interface/EffortJointInterface</hardwareInterface>
      <mechanicalReduction>1</mechanicalReduction>
    </actuator>
  </transmission>
  <transmission name="t_revolving_cab_angle">
    <type>transmission_interface/SimpleTransmission</type>
    <joint name="revolving_cab_angle">
      <hardwareInterface>hardware_interface/EffortJointInterface</hardwareInterface>
    </joint>
    <actuator name="m_revolving_cab_angle">
      <hardwareInterface>hardware_interface/EffortJointInterface</hardwareInterface>
      <mechanicalReduction>1</mechanicalReduction>
    </actuator>
  </transmission>
  <transmission name="t_boom_bucket_joint">
    <type>transmission_interface/SimpleTransmission</type>
    <joint name="boom_bucket_joint">
      <hardwareInterface>hardware_interface/EffortJointInterface</hardwareInterface>
    </joint>
    <actuator name="m_boom_bucket_joint">
      <hardwareInterface>hardware_interface/EffortJointInterface</hardwareInterface>
      <mechanicalReduction>1</mechanicalReduction>
    </actuator>
  </transmission>
  <!--    <xacro:transmission_macro limb_name="joint1" joint="boom" controller="Effort"/>
    <xacro:transmission_macro limb_name="joint" joint="boom_body_base" controller="Effort"/>
    <xacro:transmission_macro limb_name="joint" joint="boom_transalation" controller="Effort"/>  -->
  <!-- -->
  <gazebo reference="swivel_angle_front_left">
    <implicitSpringDamper>400</implicitSpringDamper>
  </gazebo>
  <gazebo reference="swivel_angle_front_right">
    <implicitSpringDamper>400</implicitSpringDamper>
  </gazebo>
  <gazebo reference="swivel_angle_rear_left">
    <implicitSpringDamper>400</implicitSpringDamper>
  </gazebo>
  <gazebo reference="swivel_angle_rear_right">
    <implicitSpringDamper>400</implicitSpringDamper>
  </gazebo>
  <gazebo>
    <!--   <self_collide>1</self_collide>
    <implicitSpringDamper>1</implicitSpringDamper>  -->
    <plugin filename="libgazebo_ros_control.so" name="gazebo_ros_control">
      <robotNamespace>/walking_excavator</robotNamespace>
      <!--  <robotSimType>steer_bot_hardware_gazebo/SteerBotHardwareGazebo</robotSimType>  -->
      <controlPeriod>0.001</controlPeriod>
      <alwaysOn>true</alwaysOn>
      <!-- just now added this lines -->
      <updateRate>100</updateRate>
    </plugin>
    <plugin filename="libgazebo_ros_p3d.so" name="p3d_base_controller">
      <alwaysOn>true</alwaysOn>
      <updateRate>50.0</updateRate>
      <bodyName>base_link</bodyName>
      <topicName>ground_truth/state</topicName>
      <gaussianNoise>0.01</gaussianNoise>
      <frameName>world</frameName>
      <xyzOffsets>0 0 0</xyzOffsets>
      <rpyOffsets>0 0 0</rpyOffsets>
    </plugin>
    <plugin filename="libgazebo_ros_imu.so" name="imu_plugin">
      <alwaysOn>true</alwaysOn>
      <bodyName>base_link</bodyName>
      <topicName>imu</topicName>
      <serviceName>imu_service</serviceName>
      <gaussianNoise>0.0</gaussianNoise>
      <updateRate>20.0</updateRate>
    </plugin>
    <!--   <plugin name="object_controller" filename="libgazebo_ros_planar_move.so">
      <commandTopic>cmd_vel</commandTopic>
      <odometryTopic>odom</odometryTopic>
      <odometryFrame>odom</odometryFrame>
      <odometryRate>20.0</odometryRate>
      <robotBaseFrame>base_link</robotBaseFrame>
    </plugin>  -->
  </gazebo>
</robot>

