<?xml version="1.0" ?>
<!-- =================================================================================== -->
<!-- |    This document was autogenerated by xacro from walking_excavator.urdf.xacro   | -->
<!-- |    EDITING THIS FILE BY HAND IS NOT RECOMMENDED                                 | -->
<!-- =================================================================================== -->
<robot name="walking_excavator" xmlns:xacro="http://www.ros.org/wiki/xacro">
  <material name="Yellow">
    <color rgba="1.0 1.0 0.0 1.0"/>
  </material>
  <material name="Gray">
    <color rgba="0.2 0.2 0.2 1.0"/>
  </material>
  <material name="Black">
    <color rgba="0 0 0 1.0"/>
  </material>
  <material name="Orange">
    <color rgba="1.0 0.423529411765 0.0392156862745 1.0"/>
  </material>
  <link name="base_link">
    <gazebo reference="base_link">
      <material>Gazebo/Orange</material>
      <gravity>true</gravity>
    </gazebo>
  </link>
  <joint name="j_walking_excavator_attachment" type="fixed">
    <parent link="base_link"/>
    <child link="body"/>
    <origin rpy="0 0 0" xyz="0 0 0"/>
  </joint>
  <link name="body">
    <inertial>
      <origin rpy="0 0 0" xyz="0 0 0"/>
      <mass value="8635"/>
      <!-- 14.1 -->
      <inertia ixx="1031.25" ixy="0.000382827" ixz="0.0010607499" iyy="2218.333333" iyz="0.1148162032" izz="3249.583333"/>
    </inertial>
    <visual>
      <material name="Yellow"/>
      <origin rpy="0 0 0" xyz="0 0 0"/>
      <geometry>
        <mesh filename="package://walking_excavator_urdf/urdf/meshes/base_link_exc1.stl" scale="0.5 0.5 0.8"/>
      </geometry>
    </visual>
    <collision>
      <material name="Red"/>
      <origin rpy="0 0 0" xyz="0 0 0"/>
      <geometry>
        <mesh filename="package://walking_excavator_urdf/urdf/meshes/base_link_exc.stl" scale="0.1 0.1 0.1"/>
      </geometry>
    </collision>
  </link>
  <joint name="revolving_cab_angle" type="revolute">
    <parent link="body"/>
    <child link="cab"/>
    <origin rpy="0 0 0" xyz="0 0 1.5"/>
    <axis xyz="0 0 1"/>
    <limit effort="10" lower="-3.05432" upper="+3.05432" velocity="3.1415926535897931"/>
  </joint>
  <link name="cab">
    <inertial>
      <origin rpy="0 0 0" xyz="0 0 3"/>
      <mass value="880.1"/>
      <!-- 14.1 -->
      <inertia ixx="150" ixy="0.000382827" ixz="0.0010607499" iyy="322.666667" iyz="0.1148162032" izz="472.666667"/>
    </inertial>
    <visual>
      <!-- <material name="Yellow"/> -->
      <material name="Orange"/>
      <origin rpy="0 0 0" xyz="0 0 0"/>
      <geometry>
        <!-- <box size="1.3 1.85 5.0"/> scale="0.001 0.001 0.001" -->
        <mesh filename="/home/dfki.uni-bremen.de/mdnkarim/catkin_ws/src/excavator-walker/walking_excavator_urdf/urdf/meshes/cab2.stl"/>
        <!-- <mesh filename="package://walking_excavator_urdf/urdf/meshes/base_boom1.stl" scale="0.5 0.5 0.8"/> -->
      </geometry>
    </visual>
    <collision>
      <material name="Red"/>
      <origin rpy="0 0 0" xyz="0.0 0.0 0.0"/>
      <geometry>
        <box size="1.3 1.85 5.0"/>
      </geometry>
    </collision>
  </link>
  <joint name="cab_base" type="fixed">
    <parent link="cab"/>
    <child link="cab_boom"/>
    <origin rpy="0 0 0" xyz="0 0 1.0"/>
    <axis xyz="0 0 1"/>
    <limit effort="10" lower="-3.05432" upper="+3.05432" velocity="3.1415926535897931"/>
  </joint>
  <link name="cab_boom">
    <inertial>
      <origin rpy="0 0 0" xyz="0 0 -2.2"/>
      <mass value="1.1"/>
      <!-- 14.1 -->
      <inertia ixx="5.01" ixy="0.000382827" ixz="0.0010607499" iyy="5.666667" iyz="0.1148162032" izz="5.666667"/>
    </inertial>
    <visual>
      <material name="Orange"/>
      <origin rpy="0 0 0" xyz="0 0 -2.2"/>
      <geometry>
        <mesh filename="package://walking_excavator_urdf/urdf/meshes/base_boom1.stl" scale="0.5 0.5 0.8"/>
      </geometry>
    </visual>
    <collision>
      <material name="Red"/>
      <origin rpy="0 0 0" xyz="0.0 0.0 0.0"/>
      <geometry>
        <box size="1.3 1.85 5.0"/>
      </geometry>
    </collision>
  </link>
  <!-- Links -->
  <link name="stabilizer_cylinder_front_left">
    <inertial>
      <origin rpy="0 0 0" xyz="0.05 0 0"/>
      <mass value="100.0"/>
      <inertia ixx="6.0061849" ixy="0.0" ixz="0.000" iyy="6.0061849" iyz="0.000" izz="6.0034656"/>
    </inertial>
    <visual>
      <material name="Black"/>
      <origin rpy="0 0 0" xyz="0 0 0"/>
      <geometry>
        <mesh filename="package://sherpa_tt_urdf/meshes/leg/steeringPivot.stl" scale="0.001 0.001 0.002"/>
      </geometry>
    </visual>
    <collision>
      <material name="Red"/>
      <origin rpy="0 0 0" xyz="0 0 -0.05"/>
      <geometry>
        <cylinder length="0.25" radius="0.08"/>
      </geometry>
    </collision>
  </link>
  <link name="swivel_base_front_left">
    <inertial>
      <origin rpy="0 0 0" xyz="0.2 0 0"/>
      <mass value="100.0"/>
      <inertia ixx="5.0034482759" ixy="0.00" ixz="0.000" iyy="5.0172413793" iyz="0.00" izz="5.0172413793"/>
    </inertial>
    <visual>
      <material name="Yellow"/>
      <origin rpy="0 0 0" xyz="0 0 0"/>
      <geometry>
        <mesh filename="package://sherpa_tt_urdf/meshes/leg/innerStrut.stl" scale="0.0002 0.006 0.0002"/>
      </geometry>
    </visual>
    <collision>
      <material name="Red"/>
      <origin rpy="0 0 0" xyz="0.2 0 0.0"/>
      <geometry>
        <box size="0.50 0.05 0.15"/>
      </geometry>
    </collision>
  </link>
  <link name="axle_front_left">
    <inertial>
      <origin rpy="0 0 0" xyz="0 0 0"/>
      <mass value="320.0"/>
      <inertia ixx="249.0103626943" ixy="1.0004710316" ixz="0.0014130947" iyy="249.0122468205" iyz="0" izz="19.2028261894"/>
    </inertial>
    <visual>
      <material name="Black"/>
      <origin rpy="0 0 0" xyz="0 0 0"/>
      <geometry>
        <mesh filename="package://sherpa_tt_urdf/meshes/leg/outerStrut.stl" scale="0.002 0.002 0.001"/>
      </geometry>
    </visual>
    <!--collision>
            <material name="Red"/>
            <origin xyz="0.15 0.0 0.08" rpy="0 0 0"/>
            <geometry>               
                <box size="0.06 0.14 0.4"/>
            </geometry>
        </collision-->
  </link>
  <link name="hub_front_left">
    <inertial>
      <origin rpy="0 0 0" xyz="0.2 0 0"/>
      <mass value="180.0"/>
      <inertia ixx="15.0008748906" ixy="0.0008748906" ixz="0.0" iyy="24.6157480315" iyz="0.0" izz="20.6148731409"/>
    </inertial>
    <visual>
      <material name="Yellow"/>
      <origin rpy="0 -1.6 0" xyz="0 0 -0.3"/>
      <geometry>
        <mesh filename="package://sherpa_tt_urdf/meshes/leg/driveUnit.stl" scale="0.002 0.002 0.002"/>
      </geometry>
    </visual>
    <!--collision>
                <material name="Red"/>
                <origin xyz="0.2 0 0.0" rpy="0 0 0"/>
                <geometry>               
                                     <box size="0.50 0.05 0.1"/>
                </geometry>
            </collision-->
  </link>
  <link name="wheel_front_left">
    <inertial>
      <origin rpy="0 0 0" xyz="0 0 0"/>
      <mass value="280.0"/>
      <inertia ixx="105.012" ixy="0" ixz="0" iyy="105.015" iyz="0" izz="215.021"/>
    </inertial>
    <visual>
      <material name="Black"/>
      <origin rpy="0 0 0" xyz="0 0 0"/>
      <geometry>
        <mesh filename="package://walking_excavator_urdf/urdf/meshes/wheel3.stl" scale="0.35 0.35 0.35"/>
      </geometry>
    </visual>
    <collision>
      <material name="Red"/>
      <origin rpy="0 0 0" xyz="0 0 -0.03 "/>
      <geometry>
        <cylinder length="0.255" radius="0.62"/>
      </geometry>
    </collision>
  </link>
  <!--    <link name="wheel_end_point_link_${limb_name}">
            <inertial>
                <origin xyz="0 0 0" rpy="0 0 0"/>
                <mass value="0.01"/>
                <inertia ixx="0.0001" ixy="0" ixz="0" iyy="0.0001" iyz="0" izz="0.0001"/>
            </inertial>      
            <geometry>      
                <box size="0.01 0.01 0.01"/>     
            </geometry>
        </link>  

        <link name="force_torque_sensor_link_${limb_name}">
            <inertial>
                <origin xyz="0 0 0.0" rpy="0 0 0"/>
                <mass value="0.001"/>
                <inertia ixx="0.001" ixy="0" ixz="0" iyy="0" iyz="0" izz="0"/>
            </inertial>
        </link>            -->
  <!-- Joint -->
  <joint name="stabilizer_angle_front_left" type="revolute">
    <parent link="body"/>
    <child link="stabilizer_cylinder_front_left"/>
    <origin rpy="0 0 0.7854" xyz="0.8 0.8 0"/>
    <axis xyz="0 0 1"/>
    <limit effort="1000" lower="-.5707963268" upper="0.581661565" velocity="0.0872664626"/>
  </joint>
  <joint name="swivel_angle_front_left" type="revolute">
    <parent link="stabilizer_cylinder_front_left"/>
    <child link="swivel_base_front_left"/>
    <origin rpy="-1.570796 0 0" xyz="0.1375 0 0"/>
    <axis xyz="0 0 1"/>
    <limit effort="10000" lower="-0.872664626" upper="0.2967059728" velocity="0.534906585"/>
  </joint>
  <joint name="adjustment_leg_length_front_left" type="prismatic">
    <parent link="swivel_base_front_left"/>
    <child link="axle_front_left"/>
    <origin rpy="0 0 0" xyz="0.4 0 0"/>
    <axis xyz="1 0 0"/>
    <!-- <limit lower="-0.297" upper="1.038" effort="100000" velocity="0.034906585"/> -->
    <limit effort="1000" lower="0" upper="1" velocity="0.2"/>
    <dynamics damping="0.7"/>
  </joint>
  <joint name="steering_angle_front_left" type="revolute">
    <parent link="axle_front_left"/>
    <child link="hub_front_left"/>
    <origin rpy="1.570796 0 0" xyz="2.04302 0.355 0.0"/>
    <!-- this 2.o will be prismatic joint cylinder -->
    <axis xyz="0 0 1"/>
    <limit effort="10000" lower="-0.0872665" upper="0.8797932658" velocity="0.534906585"/>
  </joint>
  <joint name="wheel_drive_front_left" type="continuous">
    <parent link="hub_front_left"/>
    <child link="wheel_front_left"/>
    <origin rpy="0 -1.570796 0" xyz="0.33 0 0"/>
    <axis xyz="0 0 1"/>
    <limit effort="1000" velocity="1.570796327"/>
  </joint>
  <!--  <joint name="force_torque_sensor_${limb_name}" type="fixed">
     	<parent link="hub_${limb_name}"/>
     	<child link="wheel_${limb_name}"/>	
     	<origin xyz="0.1 0 0" rpy="0 0 0"/>
     	<axis xyz="0 0 1"/>
  	<limit upper="6.28" lower="-6.28" effort="1000" velocity="1000.00"/>
  	<joint_properties damping="0.1" friction="0.80" />
     	<sensor name="force_torque" type="force_torque">
          <update_rate>30</update_rate>
        </sensor>
    </joint>        
    <gazebo>
    	<plugin name="ft_sensor" filename="libgazebo_ros_ft_sensor.so">
        <updateRate>100.0</updateRate>
        <topicName>${limb_name}/ft_sensor_topic</topicName>
        <jointName>force_torque_sensor_${limb_name}</jointName>        
        <noise>
          <type>gaussian</type>
          <mean>0.0</mean>
          <stddev>0.003</stddev> <!- change this to simulate noise -> 
        </noise>
    	</plugin>
    </gazebo> -->
  <!-- Links -->
  <link name="stabilizer_cylinder_front_right">
    <inertial>
      <origin rpy="0 0 0" xyz="0.05 0 0"/>
      <mass value="100.0"/>
      <inertia ixx="6.0061849" ixy="0.0" ixz="0.000" iyy="6.0061849" iyz="0.000" izz="6.0034656"/>
    </inertial>
    <visual>
      <material name="Black"/>
      <origin rpy="0 0 0" xyz="0 0 0"/>
      <geometry>
        <mesh filename="package://sherpa_tt_urdf/meshes/leg/steeringPivot.stl" scale="0.001 0.001 0.002"/>
      </geometry>
    </visual>
    <collision>
      <material name="Red"/>
      <origin rpy="0 0 0" xyz="0 0 -0.05"/>
      <geometry>
        <cylinder length="0.25" radius="0.08"/>
      </geometry>
    </collision>
  </link>
  <link name="swivel_base_front_right">
    <inertial>
      <origin rpy="0 0 0" xyz="0.2 0 0"/>
      <mass value="100.0"/>
      <inertia ixx="5.0034482759" ixy="0.00" ixz="0.000" iyy="5.0172413793" iyz="0.00" izz="5.0172413793"/>
    </inertial>
    <visual>
      <material name="Yellow"/>
      <origin rpy="0 0 0" xyz="0 0 0"/>
      <geometry>
        <mesh filename="package://sherpa_tt_urdf/meshes/leg/innerStrut.stl" scale="0.0002 0.006 0.0002"/>
      </geometry>
    </visual>
    <collision>
      <material name="Red"/>
      <origin rpy="0 0 0" xyz="0.2 0 0.0"/>
      <geometry>
        <box size="0.50 0.05 0.15"/>
      </geometry>
    </collision>
  </link>
  <link name="axle_front_right">
    <inertial>
      <origin rpy="0 0 0" xyz="0 0 0"/>
      <mass value="320.0"/>
      <inertia ixx="249.0103626943" ixy="1.0004710316" ixz="0.0014130947" iyy="249.0122468205" iyz="0" izz="19.2028261894"/>
    </inertial>
    <visual>
      <material name="Black"/>
      <origin rpy="0 0 0" xyz="0 0 0"/>
      <geometry>
        <mesh filename="package://sherpa_tt_urdf/meshes/leg/outerStrut.stl" scale="0.002 0.002 0.001"/>
      </geometry>
    </visual>
    <!--collision>
            <material name="Red"/>
            <origin xyz="0.15 0.0 0.08" rpy="0 0 0"/>
            <geometry>               
                <box size="0.06 0.14 0.4"/>
            </geometry>
        </collision-->
  </link>
  <link name="hub_front_right">
    <inertial>
      <origin rpy="0 0 0" xyz="0.2 0 0"/>
      <mass value="180.0"/>
      <inertia ixx="15.0008748906" ixy="0.0008748906" ixz="0.0" iyy="24.6157480315" iyz="0.0" izz="20.6148731409"/>
    </inertial>
    <visual>
      <material name="Yellow"/>
      <origin rpy="0 -1.6 0" xyz="0 0 -0.3"/>
      <geometry>
        <mesh filename="package://sherpa_tt_urdf/meshes/leg/driveUnit.stl" scale="0.002 0.002 0.002"/>
      </geometry>
    </visual>
    <!--collision>
                <material name="Red"/>
                <origin xyz="0.2 0 0.0" rpy="0 0 0"/>
                <geometry>               
                                     <box size="0.50 0.05 0.1"/>
                </geometry>
            </collision-->
  </link>
  <link name="wheel_front_right">
    <inertial>
      <origin rpy="0 0 0" xyz="0 0 0"/>
      <mass value="280.0"/>
      <inertia ixx="105.012" ixy="0" ixz="0" iyy="105.015" iyz="0" izz="215.021"/>
    </inertial>
    <visual>
      <material name="Black"/>
      <origin rpy="0 0 0" xyz="0 0 0"/>
      <geometry>
        <mesh filename="package://walking_excavator_urdf/urdf/meshes/wheel3.stl" scale="0.35 0.35 0.35"/>
      </geometry>
    </visual>
    <collision>
      <material name="Red"/>
      <origin rpy="0 0 0" xyz="0 0 -0.03 "/>
      <geometry>
        <cylinder length="0.255" radius="0.62"/>
      </geometry>
    </collision>
  </link>
  <!--    <link name="wheel_end_point_link_${limb_name}">
            <inertial>
                <origin xyz="0 0 0" rpy="0 0 0"/>
                <mass value="0.01"/>
                <inertia ixx="0.0001" ixy="0" ixz="0" iyy="0.0001" iyz="0" izz="0.0001"/>
            </inertial>      
            <geometry>      
                <box size="0.01 0.01 0.01"/>     
            </geometry>
        </link>  

        <link name="force_torque_sensor_link_${limb_name}">
            <inertial>
                <origin xyz="0 0 0.0" rpy="0 0 0"/>
                <mass value="0.001"/>
                <inertia ixx="0.001" ixy="0" ixz="0" iyy="0" iyz="0" izz="0"/>
            </inertial>
        </link>            -->
  <!-- Joint -->
  <joint name="stabilizer_angle_front_right" type="revolute">
    <parent link="body"/>
    <child link="stabilizer_cylinder_front_right"/>
    <origin rpy="0 0 -0.7854" xyz="0.8 -0.8 0"/>
    <axis xyz="0 0 1"/>
    <limit effort="1000" lower="-.5707963268" upper="0.581661565" velocity="0.0872664626"/>
  </joint>
  <joint name="swivel_angle_front_right" type="revolute">
    <parent link="stabilizer_cylinder_front_right"/>
    <child link="swivel_base_front_right"/>
    <origin rpy="-1.570796 0 0" xyz="0.1375 0 0"/>
    <axis xyz="0 0 1"/>
    <limit effort="10000" lower="-0.872664626" upper="0.2967059728" velocity="0.534906585"/>
  </joint>
  <joint name="adjustment_leg_length_front_right" type="prismatic">
    <parent link="swivel_base_front_right"/>
    <child link="axle_front_right"/>
    <origin rpy="0 0 0" xyz="0.4 0 0"/>
    <axis xyz="1 0 0"/>
    <!-- <limit lower="-0.297" upper="1.038" effort="100000" velocity="0.034906585"/> -->
    <limit effort="1000" lower="0" upper="1" velocity="0.2"/>
    <dynamics damping="0.7"/>
  </joint>
  <joint name="steering_angle_front_right" type="revolute">
    <parent link="axle_front_right"/>
    <child link="hub_front_right"/>
    <origin rpy="1.570796 0 0" xyz="2.04302 0.355 0.0"/>
    <!-- this 2.o will be prismatic joint cylinder -->
    <axis xyz="0 0 1"/>
    <limit effort="10000" lower="-0.0872665" upper="0.8797932658" velocity="0.534906585"/>
  </joint>
  <joint name="wheel_drive_front_right" type="continuous">
    <parent link="hub_front_right"/>
    <child link="wheel_front_right"/>
    <origin rpy="0 -1.570796 0" xyz="0.33 0 0"/>
    <axis xyz="0 0 1"/>
    <limit effort="1000" velocity="1.570796327"/>
  </joint>
  <!--  <joint name="force_torque_sensor_${limb_name}" type="fixed">
     	<parent link="hub_${limb_name}"/>
     	<child link="wheel_${limb_name}"/>	
     	<origin xyz="0.1 0 0" rpy="0 0 0"/>
     	<axis xyz="0 0 1"/>
  	<limit upper="6.28" lower="-6.28" effort="1000" velocity="1000.00"/>
  	<joint_properties damping="0.1" friction="0.80" />
     	<sensor name="force_torque" type="force_torque">
          <update_rate>30</update_rate>
        </sensor>
    </joint>        
    <gazebo>
    	<plugin name="ft_sensor" filename="libgazebo_ros_ft_sensor.so">
        <updateRate>100.0</updateRate>
        <topicName>${limb_name}/ft_sensor_topic</topicName>
        <jointName>force_torque_sensor_${limb_name}</jointName>        
        <noise>
          <type>gaussian</type>
          <mean>0.0</mean>
          <stddev>0.003</stddev> <!- change this to simulate noise -> 
        </noise>
    	</plugin>
    </gazebo> -->
  <!-- Links -->
  <link name="stabilizer_cylinder_rear_left">
    <inertial>
      <origin rpy="0 0 0" xyz="0.05 0 0"/>
      <mass value="100.0"/>
      <inertia ixx="6.0061849" ixy="0.0" ixz="0.000" iyy="6.0061849" iyz="0.000" izz="6.0034656"/>
    </inertial>
    <visual>
      <material name="Black"/>
      <origin rpy="0 0 0" xyz="0 0 0"/>
      <geometry>
        <mesh filename="package://sherpa_tt_urdf/meshes/leg/steeringPivot.stl" scale="0.001 0.001 0.002"/>
      </geometry>
    </visual>
    <collision>
      <material name="Red"/>
      <origin rpy="0 0 0" xyz="0 0 -0.05"/>
      <geometry>
        <cylinder length="0.25" radius="0.08"/>
      </geometry>
    </collision>
  </link>
  <link name="swivel_base_rear_left">
    <inertial>
      <origin rpy="0 0 0" xyz="0.2 0 0"/>
      <mass value="100.0"/>
      <inertia ixx="5.0034482759" ixy="0.00" ixz="0.000" iyy="5.0172413793" iyz="0.00" izz="5.0172413793"/>
    </inertial>
    <visual>
      <material name="Yellow"/>
      <origin rpy="0 0 0" xyz="0 0 0"/>
      <geometry>
        <mesh filename="package://sherpa_tt_urdf/meshes/leg/innerStrut.stl" scale="0.0002 0.006 0.0002"/>
      </geometry>
    </visual>
    <collision>
      <material name="Red"/>
      <origin rpy="0 0 0" xyz="0.2 0 0.0"/>
      <geometry>
        <box size="0.50 0.05 0.15"/>
      </geometry>
    </collision>
  </link>
  <link name="axle_rear_left">
    <inertial>
      <origin rpy="0 0 0" xyz="0 0 0"/>
      <mass value="320.0"/>
      <inertia ixx="249.0103626943" ixy="1.0004710316" ixz="0.0014130947" iyy="249.0122468205" iyz="0" izz="19.2028261894"/>
    </inertial>
    <visual>
      <material name="Black"/>
      <origin rpy="0 0 0" xyz="0 0 0"/>
      <geometry>
        <mesh filename="package://sherpa_tt_urdf/meshes/leg/outerStrut.stl" scale="0.002 0.002 0.001"/>
      </geometry>
    </visual>
    <!--collision>
            <material name="Red"/>
            <origin xyz="0.15 0.0 0.08" rpy="0 0 0"/>
            <geometry>               
                <box size="0.06 0.14 0.4"/>
            </geometry>
        </collision-->
  </link>
  <link name="hub_rear_left">
    <inertial>
      <origin rpy="0 0 0" xyz="0.2 0 0"/>
      <mass value="180.0"/>
      <inertia ixx="15.0008748906" ixy="0.0008748906" ixz="0.0" iyy="24.6157480315" iyz="0.0" izz="20.6148731409"/>
    </inertial>
    <visual>
      <material name="Yellow"/>
      <origin rpy="0 -1.6 0" xyz="0 0 -0.3"/>
      <geometry>
        <mesh filename="package://sherpa_tt_urdf/meshes/leg/driveUnit.stl" scale="0.002 0.002 0.002"/>
      </geometry>
    </visual>
    <!--collision>
                <material name="Red"/>
                <origin xyz="0.2 0 0.0" rpy="0 0 0"/>
                <geometry>               
                                     <box size="0.50 0.05 0.1"/>
                </geometry>
            </collision-->
  </link>
  <link name="wheel_rear_left">
    <inertial>
      <origin rpy="0 0 0" xyz="0 0 0"/>
      <mass value="280.0"/>
      <inertia ixx="105.012" ixy="0" ixz="0" iyy="105.015" iyz="0" izz="215.021"/>
    </inertial>
    <visual>
      <material name="Black"/>
      <origin rpy="0 0 0" xyz="0 0 0"/>
      <geometry>
        <mesh filename="package://walking_excavator_urdf/urdf/meshes/wheel3.stl" scale="0.35 0.35 0.35"/>
      </geometry>
    </visual>
    <collision>
      <material name="Red"/>
      <origin rpy="0 0 0" xyz="0 0 -0.03 "/>
      <geometry>
        <cylinder length="0.255" radius="0.62"/>
      </geometry>
    </collision>
  </link>
  <!--    <link name="wheel_end_point_link_${limb_name}">
            <inertial>
                <origin xyz="0 0 0" rpy="0 0 0"/>
                <mass value="0.01"/>
                <inertia ixx="0.0001" ixy="0" ixz="0" iyy="0.0001" iyz="0" izz="0.0001"/>
            </inertial>      
            <geometry>      
                <box size="0.01 0.01 0.01"/>     
            </geometry>
        </link>  

        <link name="force_torque_sensor_link_${limb_name}">
            <inertial>
                <origin xyz="0 0 0.0" rpy="0 0 0"/>
                <mass value="0.001"/>
                <inertia ixx="0.001" ixy="0" ixz="0" iyy="0" iyz="0" izz="0"/>
            </inertial>
        </link>            -->
  <!-- Joint -->
  <joint name="stabilizer_angle_rear_left" type="revolute">
    <parent link="body"/>
    <child link="stabilizer_cylinder_rear_left"/>
    <origin rpy="0 0 2.356194" xyz="-0.8 0.8 0"/>
    <axis xyz="0 0 1"/>
    <limit effort="1000" lower="-.5707963268" upper="0.581661565" velocity="0.0872664626"/>
  </joint>
  <joint name="swivel_angle_rear_left" type="revolute">
    <parent link="stabilizer_cylinder_rear_left"/>
    <child link="swivel_base_rear_left"/>
    <origin rpy="-1.570796 0 0" xyz="0.1375 0 0"/>
    <axis xyz="0 0 1"/>
    <limit effort="10000" lower="-0.872664626" upper="0.2967059728" velocity="0.534906585"/>
  </joint>
  <joint name="adjustment_leg_length_rear_left" type="prismatic">
    <parent link="swivel_base_rear_left"/>
    <child link="axle_rear_left"/>
    <origin rpy="0 0 0" xyz="0.4 0 0"/>
    <axis xyz="1 0 0"/>
    <!-- <limit lower="-0.297" upper="1.038" effort="100000" velocity="0.034906585"/> -->
    <limit effort="1000" lower="0" upper="1" velocity="0.2"/>
    <dynamics damping="0.7"/>
  </joint>
  <joint name="steering_angle_rear_left" type="revolute">
    <parent link="axle_rear_left"/>
    <child link="hub_rear_left"/>
    <origin rpy="1.570796 0 0" xyz="2.04302 0.355 0.0"/>
    <!-- this 2.o will be prismatic joint cylinder -->
    <axis xyz="0 0 1"/>
    <limit effort="10000" lower="-0.0872665" upper="0.8797932658" velocity="0.534906585"/>
  </joint>
  <joint name="wheel_drive_rear_left" type="continuous">
    <parent link="hub_rear_left"/>
    <child link="wheel_rear_left"/>
    <origin rpy="0 -1.570796 0" xyz="0.33 0 0"/>
    <axis xyz="0 0 1"/>
    <limit effort="1000" velocity="1.570796327"/>
  </joint>
  <!--  <joint name="force_torque_sensor_${limb_name}" type="fixed">
     	<parent link="hub_${limb_name}"/>
     	<child link="wheel_${limb_name}"/>	
     	<origin xyz="0.1 0 0" rpy="0 0 0"/>
     	<axis xyz="0 0 1"/>
  	<limit upper="6.28" lower="-6.28" effort="1000" velocity="1000.00"/>
  	<joint_properties damping="0.1" friction="0.80" />
     	<sensor name="force_torque" type="force_torque">
          <update_rate>30</update_rate>
        </sensor>
    </joint>        
    <gazebo>
    	<plugin name="ft_sensor" filename="libgazebo_ros_ft_sensor.so">
        <updateRate>100.0</updateRate>
        <topicName>${limb_name}/ft_sensor_topic</topicName>
        <jointName>force_torque_sensor_${limb_name}</jointName>        
        <noise>
          <type>gaussian</type>
          <mean>0.0</mean>
          <stddev>0.003</stddev> <!- change this to simulate noise -> 
        </noise>
    	</plugin>
    </gazebo> -->
  <!-- Links -->
  <link name="stabilizer_cylinder_rear_right">
    <inertial>
      <origin rpy="0 0 0" xyz="0.05 0 0"/>
      <mass value="100.0"/>
      <inertia ixx="6.0061849" ixy="0.0" ixz="0.000" iyy="6.0061849" iyz="0.000" izz="6.0034656"/>
    </inertial>
    <visual>
      <material name="Black"/>
      <origin rpy="0 0 0" xyz="0 0 0"/>
      <geometry>
        <mesh filename="package://sherpa_tt_urdf/meshes/leg/steeringPivot.stl" scale="0.001 0.001 0.002"/>
      </geometry>
    </visual>
    <collision>
      <material name="Red"/>
      <origin rpy="0 0 0" xyz="0 0 -0.05"/>
      <geometry>
        <cylinder length="0.25" radius="0.08"/>
      </geometry>
    </collision>
  </link>
  <link name="swivel_base_rear_right">
    <inertial>
      <origin rpy="0 0 0" xyz="0.2 0 0"/>
      <mass value="100.0"/>
      <inertia ixx="5.0034482759" ixy="0.00" ixz="0.000" iyy="5.0172413793" iyz="0.00" izz="5.0172413793"/>
    </inertial>
    <visual>
      <material name="Yellow"/>
      <origin rpy="0 0 0" xyz="0 0 0"/>
      <geometry>
        <mesh filename="package://sherpa_tt_urdf/meshes/leg/innerStrut.stl" scale="0.0002 0.006 0.0002"/>
      </geometry>
    </visual>
    <collision>
      <material name="Red"/>
      <origin rpy="0 0 0" xyz="0.2 0 0.0"/>
      <geometry>
        <box size="0.50 0.05 0.15"/>
      </geometry>
    </collision>
  </link>
  <link name="axle_rear_right">
    <inertial>
      <origin rpy="0 0 0" xyz="0 0 0"/>
      <mass value="320.0"/>
      <inertia ixx="249.0103626943" ixy="1.0004710316" ixz="0.0014130947" iyy="249.0122468205" iyz="0" izz="19.2028261894"/>
    </inertial>
    <visual>
      <material name="Black"/>
      <origin rpy="0 0 0" xyz="0 0 0"/>
      <geometry>
        <mesh filename="package://sherpa_tt_urdf/meshes/leg/outerStrut.stl" scale="0.002 0.002 0.001"/>
      </geometry>
    </visual>
    <!--collision>
            <material name="Red"/>
            <origin xyz="0.15 0.0 0.08" rpy="0 0 0"/>
            <geometry>               
                <box size="0.06 0.14 0.4"/>
            </geometry>
        </collision-->
  </link>
  <link name="hub_rear_right">
    <inertial>
      <origin rpy="0 0 0" xyz="0.2 0 0"/>
      <mass value="180.0"/>
      <inertia ixx="15.0008748906" ixy="0.0008748906" ixz="0.0" iyy="24.6157480315" iyz="0.0" izz="20.6148731409"/>
    </inertial>
    <visual>
      <material name="Yellow"/>
      <origin rpy="0 -1.6 0" xyz="0 0 -0.3"/>
      <geometry>
        <mesh filename="package://sherpa_tt_urdf/meshes/leg/driveUnit.stl" scale="0.002 0.002 0.002"/>
      </geometry>
    </visual>
    <!--collision>
                <material name="Red"/>
                <origin xyz="0.2 0 0.0" rpy="0 0 0"/>
                <geometry>               
                                     <box size="0.50 0.05 0.1"/>
                </geometry>
            </collision-->
  </link>
  <link name="wheel_rear_right">
    <inertial>
      <origin rpy="0 0 0" xyz="0 0 0"/>
      <mass value="280.0"/>
      <inertia ixx="105.012" ixy="0" ixz="0" iyy="105.015" iyz="0" izz="215.021"/>
    </inertial>
    <visual>
      <material name="Black"/>
      <origin rpy="0 0 0" xyz="0 0 0"/>
      <geometry>
        <mesh filename="package://walking_excavator_urdf/urdf/meshes/wheel3.stl" scale="0.35 0.35 0.35"/>
      </geometry>
    </visual>
    <collision>
      <material name="Red"/>
      <origin rpy="0 0 0" xyz="0 0 -0.03 "/>
      <geometry>
        <cylinder length="0.255" radius="0.62"/>
      </geometry>
    </collision>
  </link>
  <!--    <link name="wheel_end_point_link_${limb_name}">
            <inertial>
                <origin xyz="0 0 0" rpy="0 0 0"/>
                <mass value="0.01"/>
                <inertia ixx="0.0001" ixy="0" ixz="0" iyy="0.0001" iyz="0" izz="0.0001"/>
            </inertial>      
            <geometry>      
                <box size="0.01 0.01 0.01"/>     
            </geometry>
        </link>  

        <link name="force_torque_sensor_link_${limb_name}">
            <inertial>
                <origin xyz="0 0 0.0" rpy="0 0 0"/>
                <mass value="0.001"/>
                <inertia ixx="0.001" ixy="0" ixz="0" iyy="0" iyz="0" izz="0"/>
            </inertial>
        </link>            -->
  <!-- Joint -->
  <joint name="stabilizer_angle_rear_right" type="revolute">
    <parent link="body"/>
    <child link="stabilizer_cylinder_rear_right"/>
    <origin rpy="0 0 -2.356194" xyz="-0.8 -0.8 0"/>
    <axis xyz="0 0 1"/>
    <limit effort="1000" lower="-.5707963268" upper="0.581661565" velocity="0.0872664626"/>
  </joint>
  <joint name="swivel_angle_rear_right" type="revolute">
    <parent link="stabilizer_cylinder_rear_right"/>
    <child link="swivel_base_rear_right"/>
    <origin rpy="-1.570796 0 0" xyz="0.1375 0 0"/>
    <axis xyz="0 0 1"/>
    <limit effort="10000" lower="-0.872664626" upper="0.2967059728" velocity="0.534906585"/>
  </joint>
  <joint name="adjustment_leg_length_rear_right" type="prismatic">
    <parent link="swivel_base_rear_right"/>
    <child link="axle_rear_right"/>
    <origin rpy="0 0 0" xyz="0.4 0 0"/>
    <axis xyz="1 0 0"/>
    <!-- <limit lower="-0.297" upper="1.038" effort="100000" velocity="0.034906585"/> -->
    <limit effort="1000" lower="0" upper="1" velocity="0.2"/>
    <dynamics damping="0.7"/>
  </joint>
  <joint name="steering_angle_rear_right" type="revolute">
    <parent link="axle_rear_right"/>
    <child link="hub_rear_right"/>
    <origin rpy="1.570796 0 0" xyz="2.04302 0.355 0.0"/>
    <!-- this 2.o will be prismatic joint cylinder -->
    <axis xyz="0 0 1"/>
    <limit effort="10000" lower="-0.0872665" upper="0.8797932658" velocity="0.534906585"/>
  </joint>
  <joint name="wheel_drive_rear_right" type="continuous">
    <parent link="hub_rear_right"/>
    <child link="wheel_rear_right"/>
    <origin rpy="0 -1.570796 0" xyz="0.33 0 0"/>
    <axis xyz="0 0 1"/>
    <limit effort="1000" velocity="1.570796327"/>
  </joint>
  <!--  <joint name="force_torque_sensor_${limb_name}" type="fixed">
     	<parent link="hub_${limb_name}"/>
     	<child link="wheel_${limb_name}"/>	
     	<origin xyz="0.1 0 0" rpy="0 0 0"/>
     	<axis xyz="0 0 1"/>
  	<limit upper="6.28" lower="-6.28" effort="1000" velocity="1000.00"/>
  	<joint_properties damping="0.1" friction="0.80" />
     	<sensor name="force_torque" type="force_torque">
          <update_rate>30</update_rate>
        </sensor>
    </joint>        
    <gazebo>
    	<plugin name="ft_sensor" filename="libgazebo_ros_ft_sensor.so">
        <updateRate>100.0</updateRate>
        <topicName>${limb_name}/ft_sensor_topic</topicName>
        <jointName>force_torque_sensor_${limb_name}</jointName>        
        <noise>
          <type>gaussian</type>
          <mean>0.0</mean>
          <stddev>0.003</stddev> <!- change this to simulate noise -> 
        </noise>
    	</plugin>
    </gazebo> -->
  <!--   <xacro:include filename="$(find walking_excavator_urdf)/xacro_manzi/manipulator.urdf.xacro"/> -->
  <transmission name="t_stabilizer_angle_front_left">
    <type>transmission_interface/SimpleTransmission</type>
    <joint name="stabilizer_angle_front_left">
      <hardwareInterface>hardware_interface/EffortJointInterface</hardwareInterface>
    </joint>
    <actuator name="m_stabilizer_angle_front_left">
      <hardwareInterface>hardware_interface/EffortJointInterface</hardwareInterface>
      <mechanicalReduction>1</mechanicalReduction>
    </actuator>
  </transmission>
  <transmission name="t_swivel_angle_front_left">
    <type>transmission_interface/SimpleTransmission</type>
    <joint name="swivel_angle_front_left">
      <hardwareInterface>hardware_interface/EffortJointInterface</hardwareInterface>
    </joint>
    <actuator name="m_swivel_angle_front_left">
      <hardwareInterface>hardware_interface/EffortJointInterface</hardwareInterface>
      <mechanicalReduction>1</mechanicalReduction>
    </actuator>
  </transmission>
  <transmission name="t_adjustment_leg_length_front_left">
    <type>transmission_interface/SimpleTransmission</type>
    <joint name="adjustment_leg_length_front_left">
      <hardwareInterface>hardware_interface/EffortJointInterface</hardwareInterface>
    </joint>
    <actuator name="m_adjustment_leg_length_front_left">
      <hardwareInterface>hardware_interface/EffortJointInterface</hardwareInterface>
      <mechanicalReduction>1</mechanicalReduction>
    </actuator>
  </transmission>
  <transmission name="t_steering_angle_front_left">
    <type>transmission_interface/SimpleTransmission</type>
    <joint name="steering_angle_front_left">
      <hardwareInterface>hardware_interface/EffortJointInterface</hardwareInterface>
    </joint>
    <actuator name="m_steering_angle_front_left">
      <hardwareInterface>hardware_interface/EffortJointInterface</hardwareInterface>
      <mechanicalReduction>1</mechanicalReduction>
    </actuator>
  </transmission>
  <transmission name="t_wheel_drive_front_left">
    <type>transmission_interface/SimpleTransmission</type>
    <joint name="wheel_drive_front_left">
      <hardwareInterface>hardware_interface/EffortJointInterface</hardwareInterface>
    </joint>
    <actuator name="m_wheel_drive_front_left">
      <hardwareInterface>hardware_interface/EffortJointInterface</hardwareInterface>
      <mechanicalReduction>1</mechanicalReduction>
    </actuator>
  </transmission>
  <transmission name="t_stabilizer_angle_front_right">
    <type>transmission_interface/SimpleTransmission</type>
    <joint name="stabilizer_angle_front_right">
      <hardwareInterface>hardware_interface/EffortJointInterface</hardwareInterface>
    </joint>
    <actuator name="m_stabilizer_angle_front_right">
      <hardwareInterface>hardware_interface/EffortJointInterface</hardwareInterface>
      <mechanicalReduction>1</mechanicalReduction>
    </actuator>
  </transmission>
  <transmission name="t_swivel_angle_front_right">
    <type>transmission_interface/SimpleTransmission</type>
    <joint name="swivel_angle_front_right">
      <hardwareInterface>hardware_interface/EffortJointInterface</hardwareInterface>
    </joint>
    <actuator name="m_swivel_angle_front_right">
      <hardwareInterface>hardware_interface/EffortJointInterface</hardwareInterface>
      <mechanicalReduction>1</mechanicalReduction>
    </actuator>
  </transmission>
  <transmission name="t_adjustment_leg_length_front_right">
    <type>transmission_interface/SimpleTransmission</type>
    <joint name="adjustment_leg_length_front_right">
      <hardwareInterface>hardware_interface/EffortJointInterface</hardwareInterface>
    </joint>
    <actuator name="m_adjustment_leg_length_front_right">
      <hardwareInterface>hardware_interface/EffortJointInterface</hardwareInterface>
      <mechanicalReduction>1</mechanicalReduction>
    </actuator>
  </transmission>
  <transmission name="t_steering_angle_front_right">
    <type>transmission_interface/SimpleTransmission</type>
    <joint name="steering_angle_front_right">
      <hardwareInterface>hardware_interface/EffortJointInterface</hardwareInterface>
    </joint>
    <actuator name="m_steering_angle_front_right">
      <hardwareInterface>hardware_interface/EffortJointInterface</hardwareInterface>
      <mechanicalReduction>1</mechanicalReduction>
    </actuator>
  </transmission>
  <transmission name="t_wheel_drive_front_right">
    <type>transmission_interface/SimpleTransmission</type>
    <joint name="wheel_drive_front_right">
      <hardwareInterface>hardware_interface/EffortJointInterface</hardwareInterface>
    </joint>
    <actuator name="m_wheel_drive_front_right">
      <hardwareInterface>hardware_interface/EffortJointInterface</hardwareInterface>
      <mechanicalReduction>1</mechanicalReduction>
    </actuator>
  </transmission>
  <transmission name="t_stabilizer_angle_rear_left">
    <type>transmission_interface/SimpleTransmission</type>
    <joint name="stabilizer_angle_rear_left">
      <hardwareInterface>hardware_interface/EffortJointInterface</hardwareInterface>
    </joint>
    <actuator name="m_stabilizer_angle_rear_left">
      <hardwareInterface>hardware_interface/EffortJointInterface</hardwareInterface>
      <mechanicalReduction>1</mechanicalReduction>
    </actuator>
  </transmission>
  <transmission name="t_swivel_angle_rear_left">
    <type>transmission_interface/SimpleTransmission</type>
    <joint name="swivel_angle_rear_left">
      <hardwareInterface>hardware_interface/EffortJointInterface</hardwareInterface>
    </joint>
    <actuator name="m_swivel_angle_rear_left">
      <hardwareInterface>hardware_interface/EffortJointInterface</hardwareInterface>
      <mechanicalReduction>1</mechanicalReduction>
    </actuator>
  </transmission>
  <transmission name="t_adjustment_leg_length_rear_left">
    <type>transmission_interface/SimpleTransmission</type>
    <joint name="adjustment_leg_length_rear_left">
      <hardwareInterface>hardware_interface/EffortJointInterface</hardwareInterface>
    </joint>
    <actuator name="m_adjustment_leg_length_rear_left">
      <hardwareInterface>hardware_interface/EffortJointInterface</hardwareInterface>
      <mechanicalReduction>1</mechanicalReduction>
    </actuator>
  </transmission>
  <transmission name="t_steering_angle_rear_left">
    <type>transmission_interface/SimpleTransmission</type>
    <joint name="steering_angle_rear_left">
      <hardwareInterface>hardware_interface/EffortJointInterface</hardwareInterface>
    </joint>
    <actuator name="m_steering_angle_rear_left">
      <hardwareInterface>hardware_interface/EffortJointInterface</hardwareInterface>
      <mechanicalReduction>1</mechanicalReduction>
    </actuator>
  </transmission>
  <transmission name="t_wheel_drive_rear_left">
    <type>transmission_interface/SimpleTransmission</type>
    <joint name="wheel_drive_rear_left">
      <hardwareInterface>hardware_interface/EffortJointInterface</hardwareInterface>
    </joint>
    <actuator name="m_wheel_drive_rear_left">
      <hardwareInterface>hardware_interface/EffortJointInterface</hardwareInterface>
      <mechanicalReduction>1</mechanicalReduction>
    </actuator>
  </transmission>
  <transmission name="t_stabilizer_angle_rear_right">
    <type>transmission_interface/SimpleTransmission</type>
    <joint name="stabilizer_angle_rear_right">
      <hardwareInterface>hardware_interface/EffortJointInterface</hardwareInterface>
    </joint>
    <actuator name="m_stabilizer_angle_rear_right">
      <hardwareInterface>hardware_interface/EffortJointInterface</hardwareInterface>
      <mechanicalReduction>1</mechanicalReduction>
    </actuator>
  </transmission>
  <transmission name="t_swivel_angle_rear_right">
    <type>transmission_interface/SimpleTransmission</type>
    <joint name="swivel_angle_rear_right">
      <hardwareInterface>hardware_interface/EffortJointInterface</hardwareInterface>
    </joint>
    <actuator name="m_swivel_angle_rear_right">
      <hardwareInterface>hardware_interface/EffortJointInterface</hardwareInterface>
      <mechanicalReduction>1</mechanicalReduction>
    </actuator>
  </transmission>
  <transmission name="t_adjustment_leg_length_rear_right">
    <type>transmission_interface/SimpleTransmission</type>
    <joint name="adjustment_leg_length_rear_right">
      <hardwareInterface>hardware_interface/EffortJointInterface</hardwareInterface>
    </joint>
    <actuator name="m_adjustment_leg_length_rear_right">
      <hardwareInterface>hardware_interface/EffortJointInterface</hardwareInterface>
      <mechanicalReduction>1</mechanicalReduction>
    </actuator>
  </transmission>
  <transmission name="t_steering_angle_rear_right">
    <type>transmission_interface/SimpleTransmission</type>
    <joint name="steering_angle_rear_right">
      <hardwareInterface>hardware_interface/EffortJointInterface</hardwareInterface>
    </joint>
    <actuator name="m_steering_angle_rear_right">
      <hardwareInterface>hardware_interface/EffortJointInterface</hardwareInterface>
      <mechanicalReduction>1</mechanicalReduction>
    </actuator>
  </transmission>
  <transmission name="t_wheel_drive_rear_right">
    <type>transmission_interface/SimpleTransmission</type>
    <joint name="wheel_drive_rear_right">
      <hardwareInterface>hardware_interface/EffortJointInterface</hardwareInterface>
    </joint>
    <actuator name="m_wheel_drive_rear_right">
      <hardwareInterface>hardware_interface/EffortJointInterface</hardwareInterface>
      <mechanicalReduction>1</mechanicalReduction>
    </actuator>
  </transmission>
  <!-- <xacro:include filename="$(find walking_excavator_urdf)/xacro_manzi/manipulator_transmission.urdf.xacro"/>
    <gazebo>
        <plugin name="gazebo_ros_control" filename="libgazebo_ros_control.so">
            <robotNamespace>/sherpa_tt</robotNamespace>
            <controlPeriod>0.01</controlPeriod>
        </plugin>
    </gazebo>  -->
</robot>

